Workbook

Sheet Financial Analysis

Sheet Histriocial FS
H1: Figures in Rs. Crores
D2: =" Historical Financial Statement-"&'Data Sheet '!B1 -> Historical Financial Statement-NESTLE INDIA LTD
B3: Year | C3: ='Data Sheet '!B16 -> 44561 | D3: ='Data Sheet '!C16 -> 44926 | E3: ='Data Sheet '!D16 -> 45291 | F3: ='Data Sheet '!E16 -> 45382 | G3: ='Data Sheet '!F16 -> 45747 | H3: ='Data Sheet '!G16 -> 46112 | I3: LTM
A5: # | B5: Income Statement
B6: Sales | C6: =IFERROR('Data Sheet '!B17,0) -> 14740.59 | D6: =IFERROR('Data Sheet '!C17,0) -> 16896.96 | E6: =IFERROR('Data Sheet '!D17,0) -> 19126.3 | F6: =IFERROR('Data Sheet '!E17,0) -> 24393.89 | G6: =IFERROR('Data Sheet '!F17,0) -> 20201.56 | H6: =IFERROR('Data Sheet '!G17,0) -> 23154.6 | I6: =IFERROR(SUM('Data Sheet '!H42:K42),0) -> 23154.6
B7: Sales Growth | D7: =D6/C6-1 -> 0.1462879 | E7: =E6/D6-1 -> 0.13193734 | F7: =F6/E6-1 -> 0.27541082 | G7: =G6/F6-1 -> -0.17185984 | H7: =H6/G6-1 -> 0.14617881 | I7: =I6/H6-1 -> 0
B9: COGS | C9: =IFERROR(SUM('Data Sheet '!B18,'Data Sheet '!B20,,'Data Sheet '!B21,'Data Sheet '!B22)-1*'Data Sheet '!B19,0) -> 8521.15 | D9: =IFERROR(SUM('Data Sheet '!C18,'Data Sheet '!C20,,'Data Sheet '!C21,'Data Sheet '!C22)-1*'Data Sheet '!C19,0) -> 10221.7 | E9: =IFERROR(SUM('Data Sheet '!D18,'Data Sheet '!D20,,'Data Sheet '!D21,'Data Sheet '!D22)-1*'Data Sheet '!D19,0) -> 10281.89 | F9: =IFERROR(SUM('Data Sheet '!E18,'Data Sheet '!E20,,'Data Sheet '!E21,'Data Sheet '!E22)-1*'Data Sheet '!E19,0) -> 14101.72 | G9: =IFERROR(SUM('Data Sheet '!F18,'Data Sheet '!F20,,'Data Sheet '!F21,'Data Sheet '!F22)-1*'Data Sheet '!F19,0) -> 11692.86 | H9: =IFERROR(SUM('Data Sheet '!G18,'Data Sheet '!G20,,'Data Sheet '!G21,'Data Sheet '!G22)-1*'Data Sheet '!G19,0) -> 13627.64 | I9: =IFERROR(SUM('Data Sheet '!H43:K43),0) -> 17845.15
B10: Cogs% of sale | C10: =C9/C6 -> 0.57807388 | D10: =D9/D6 -> 0.60494314 | E10: =E9/E6 -> 0.53757862 | F10: =F9/F6 -> 0.5780841 | G10: =G9/G6 -> 0.57880976 | H10: =H9/H6 -> 0.58855001 | I10: =I9/I6 -> 0.77069567
B12: Gross Profit | C12: =C6-C9 -> 6219.44 | D12: =D6-D9 -> 6675.26 | E12: =E6-E9 -> 8844.41 | F12: =F6-F9 -> 10292.17 | G12: =G6-G9 -> 8508.7 | H12: =H6-H9 -> 9526.96 | I12: =I6-I9 -> 5309.45
B13: Gross Margin | C13: =C12/C9 -> 0.7298827 | D13: =D12/D9 -> 0.65304793 | E13: =E12/E9 -> 0.86019302 | F13: =F12/F9 -> 0.7298521 | G13: =G12/G9 -> 0.72768339 | H13: =H12/H9 -> 0.69909097 | I13: =I12/I9 -> 0.29752902
B15: S&G Expences | C15: =IFERROR(SUM('Data Sheet '!B23:B24),0) -> 2657.04 | D15: =IFERROR(SUM('Data Sheet '!C23:C24),0) -> 2968.97 | E15: =IFERROR(SUM('Data Sheet '!D23:D24),0) -> 4373.42 | F15: =IFERROR(SUM('Data Sheet '!E23:E24),0) -> 4449.05 | G15: =IFERROR(SUM('Data Sheet '!F23:F24),0) -> 3737.37 | H15: =IFERROR(SUM('Data Sheet '!G23:G24),0) -> 4220 | I15: =IFERROR(SUM('Data Sheet '!H23:H24),0) -> 0
B16: S&G Expences% of sales | C16: =C15/C6 -> 0.1802533 | D16: =D15/D6 -> 0.17571031 | E16: =E15/E6 -> 0.22866001 | F16: =F15/F6 -> 0.18238379 | G16: =G15/G6 -> 0.18500403 | H16: =H15/H6 -> 0.1822532 | I16: =I15/I6 -> 0
B18: EBITDA | C18: =C12-C15 -> 3562.4 | D18: =D12-D15 -> 3706.29 | E18: =E12-E15 -> 4470.99 | F18: =F12-F15 -> 5843.12 | G18: =G12-G15 -> 4771.33 | H18: =H12-H15 -> 5306.96 | I18: =I12-I15 -> 5309.45
B19: EBITDA Margin | C19: =C18/C6 -> 0.24167282 | D19: =D18/D6 -> 0.21934656 | E19: =E18/E6 -> 0.23376137 | F19: =F18/F6 -> 0.23953211 | G19: =G18/G6 -> 0.23618622 | H19: =H18/H6 -> 0.22919679 | I19: =I18/I6 -> 0.22930433
B21: Interest | C21: =IFERROR('Data Sheet '!B27,0) -> 201.68 | D21: =IFERROR('Data Sheet '!C27,0) -> 154.57 | E21: =IFERROR('Data Sheet '!D27,0) -> 119.29 | F21: =IFERROR('Data Sheet '!E27,0) -> 145.49 | G21: =IFERROR('Data Sheet '!F27,0) -> 136 | H21: =IFERROR('Data Sheet '!G27,0) -> 158.31 | I21: =IFERROR(SUM('Data Sheet '!H46:K46),0) -> 158.31
B22: Interest% of sales | C22: =C21/C6 -> 0.013681949 | D22: =D21/D6 -> 0.0091477994 | E22: =E21/E6 -> 0.0062369617 | F22: =F21/F6 -> 0.0059641984 | G22: =G21/G6 -> 0.0067321534 | H22: =H21/H6 -> 0.0068370864 | I22: =I21/I6 -> 0.0068370864
B24: Depreciation | C24: =IFERROR('Data Sheet '!B26,0) -> 391.02 | D24: =IFERROR('Data Sheet '!C26,0) -> 403.01 | E24: =IFERROR('Data Sheet '!D26,0) -> 428.91 | F24: =IFERROR('Data Sheet '!E26,0) -> 567.75 | G24: =IFERROR('Data Sheet '!F26,0) -> 539.92 | H24: =IFERROR('Data Sheet '!G26,0) -> 699.23 | I24: =IFERROR(SUM('Data Sheet '!H45:K45),0) -> 699.23
B25: Depreciation% of sales | C25: =C24/C9 -> 0.045888172 | D25: =D24/D9 -> 0.039426906 | E25: =E24/E9 -> 0.041715093 | F25: =F24/F9 -> 0.040261046 | G25: =G24/G9 -> 0.046175187 | H25: =H24/H9 -> 0.051309691 | I25: =I24/I9 -> 0.039183195
B27: Earning before Tax (EBT) | C27: =C18-(C21+C24) -> 2969.7 | D27: =D18-(D21+D24) -> 3148.71 | E27: =E18-(E21+E24) -> 3922.79 | F27: =F18-(F21+F24) -> 5129.88 | G27: =G18-(G21+G24) -> 4095.41 | H27: =H18-(H21+H24) -> 4449.42 | I27: =I18-(I21+I24) -> 4451.91
B28: EBT% Sale | C28: =C27/C6 -> 0.20146412 | D28: =D27/D6 -> 0.18634772 | E28: =E27/E6 -> 0.20509926 | F28: =F27/F6 -> 0.21029364 | G28: =G27/G6 -> 0.20272741 | H28: =H27/H6 -> 0.19216138 | I28: =I27/I6 -> 0.19226892
B30: Tax | C30: =IFERROR('Data Sheet '!B29,0) -> 738.91 | D30: =IFERROR('Data Sheet '!C29,0) -> 865.45 | E30: =IFERROR('Data Sheet '!D29,0) -> 1039.62 | F30: =IFERROR('Data Sheet '!E29,0) -> 1356.03 | G30: =IFERROR('Data Sheet '!F29,0) -> 1132.97 | H30: =IFERROR('Data Sheet '!G29,0) -> 1065.05 | I30: =IFERROR(SUM('Data Sheet '!H48:K48),0) -> 1065.05
B31: Effective Tax Rate | C31: =C30/C27 -> 0.24881638 | D31: =D30/D27 -> 0.27485859 | E31: =E30/E27 -> 0.26502056 | F31: =F30/F27 -> 0.26433952 | G31: =G30/G27 -> 0.27664385 | H31: =H30/H27 -> 0.23936828 | I31: =I30/I27 -> 0.2392344
B33: Net Profit | C33: =C27-C30 -> 2230.79 | D33: =D27-D30 -> 2283.26 | E33: =E27-E30 -> 2883.17 | F33: =F27-F30 -> 3773.85 | G33: =G27-G30 -> 2962.44 | H33: =H27-H30 -> 3384.37 | I33: =I27-I30 -> 3386.86
B34: Net Margin | C34: =C33/C6 -> 0.15133655 | D34: =D33/D6 -> 0.13512845 | E34: =E33/E6 -> 0.15074374 | F34: =F33/F6 -> 0.15470472 | G34: =G33/G6 -> 0.14664412 | H34: =H33/H6 -> 0.14616405 | I34: =I33/I6 -> 0.14627158
B36: No. of Equity Shares | C36: =IFERROR('Data Sheet '!B93,0) -> 192.8 | D36: =IFERROR('Data Sheet '!C93,0) -> 192.8 | E36: =IFERROR('Data Sheet '!D93,0) -> 192.8 | F36: =IFERROR('Data Sheet '!E93,0) -> 192.83 | G36: =IFERROR('Data Sheet '!F93,0) -> 192.83 | H36: =IFERROR('Data Sheet '!G93,0) -> 192.83 | I36: =H36 -> 192.83
B38: Earning per Shares | C38: =C33/C36 -> 11.570488 | D38: =D33/D36 -> 11.842635 | E38: =E33/E36 -> 14.954201 | F38: =F33/F36 -> 19.570866 | G38: =G33/G36 -> 15.362962 | H38: =H33/H36 -> 17.551055 | I38: =I33/I36 -> 17.563968
B39: EPS Growth% | D39: =D38/C38-1 -> 0.023520815 | E39: =E38/D38-1 -> 0.26274275 | F39: =F38/E38-1 -> 0.30872022 | G39: =G38/F38-1 -> -0.21500855 | H39: =H38/G38-1 -> 0.14242651 | I39: =I38/H38-1 -> 0.00073573516
B41: Dividend Per Shares | C41: =IFERROR('Data Sheet '!B31/'Data Sheet '!B93,0) -> 10.002075 | D41: =IFERROR('Data Sheet '!C31/'Data Sheet '!C93,0) -> 11.002282 | E41: =IFERROR('Data Sheet '!D31/'Data Sheet '!D93,0) -> 8.7018154 | F41: =IFERROR('Data Sheet '!E31/'Data Sheet '!E93,0) -> 16.100814 | G41: =IFERROR('Data Sheet '!F31/'Data Sheet '!F93,0) -> 13.5007 | H41: =IFERROR('Data Sheet '!G31/'Data Sheet '!G93,0) -> 12 | I41: =IFERROR('Data Sheet '!H31/'Data Sheet '!H93,0) -> 0
B42: Dividend payout ratio | C42: =C41/C38 -> 0.86444712 | D42: =D41/D38 -> 0.92904006 | E42: =E41/E38 -> 0.5818977 | F42: =F41/F38 -> 0.82269301 | G42: =G41/G38 -> 0.87878236 | H42: =H41/H38 -> 0.68371957 | I42: =I41/I38 -> 0
B44: Retained Earnings | C44: =IFERROR(IF(C38>C41,1-C42,0),0) -> 0.13555288 | D44: =IFERROR(IF(D38>D41,1-D42,0),0) -> 0.070959943 | E44: =IFERROR(IF(E38>E41,1-E42,0),0) -> 0.4181023 | F44: =IFERROR(IF(F38>F41,1-F42,0),0) -> 0.17730699 | G44: =IFERROR(IF(G38>G41,1-G42,0),0) -> 0.12121764 | H44: =IFERROR(IF(H38>H41,1-H42,0),0) -> 0.31628043
A47: # | B47: Balance Sheet | C47: 44561 | D47: 44926 | E47: 45291 | F47: 45382 | G47: 45747 | H47: 46112
B48: Equity Share Capital | C48: =IFERROR('Data Sheet '!B57,0) -> 96.42 | D48: =IFERROR('Data Sheet '!C57,0) -> 96.42 | E48: =IFERROR('Data Sheet '!D57,0) -> 96.42 | F48: =IFERROR('Data Sheet '!E57,0) -> 96.42 | G48: =IFERROR('Data Sheet '!F57,0) -> 96.42 | H48: =IFERROR('Data Sheet '!G57,0) -> 192.83
B49: Reserves | C49: =IFERROR('Data Sheet '!B58,0) -> 1849.96 | D49: =IFERROR('Data Sheet '!C58,0) -> 2362.75 | E49: =IFERROR('Data Sheet '!D58,0) -> 2362.75 | F49: =IFERROR('Data Sheet '!E58,0) -> 3244.47 | G49: =IFERROR('Data Sheet '!F58,0) -> 4020.73 | H49: =IFERROR('Data Sheet '!G58,0) -> 5116.41
B50: Borrowings | C50: =IFERROR('Data Sheet '!B59,0) -> 266.46 | D50: =IFERROR('Data Sheet '!C59,0) -> 270.52 | E50: =IFERROR('Data Sheet '!D59,0) -> 270.52 | F50: =IFERROR('Data Sheet '!E59,0) -> 344.53 | G50: =IFERROR('Data Sheet '!F59,0) -> 1166.85 | H50: =IFERROR('Data Sheet '!G59,0) -> 444.16
B51: Other Liabilities | C51: =IFERROR('Data Sheet '!B60,0) -> 6021.29 | D51: =IFERROR('Data Sheet '!C60,0) -> 6249.05 | E51: =IFERROR('Data Sheet '!D60,0) -> 6249.05 | F51: =IFERROR('Data Sheet '!E60,0) -> 6837.64 | G51: =IFERROR('Data Sheet '!F60,0) -> 7039.89 | H51: =IFERROR('Data Sheet '!G60,0) -> 7603.77
B52: Total Liabilites | C52: =IFERROR('Data Sheet '!B61,0) -> 8234.13 | D52: =IFERROR('Data Sheet '!C61,0) -> 8978.74 | E52: =IFERROR('Data Sheet '!D61,0) -> 8978.74 | F52: =IFERROR('Data Sheet '!E61,0) -> 10523.06 | G52: =IFERROR('Data Sheet '!F61,0) -> 12323.89 | H52: =IFERROR('Data Sheet '!G61,0) -> 13357.17
B54: Fixed Assest Net Block | C54: =IFERROR('Data Sheet '!B62,0) -> 2994.67 | D54: =IFERROR('Data Sheet '!C62,0) -> 3043.7 | E54: =IFERROR('Data Sheet '!D62,0) -> 3043.7 | F54: =IFERROR('Data Sheet '!E62,0) -> 3460.25 | G54: =IFERROR('Data Sheet '!F62,0) -> 5473.61 | H54: =IFERROR('Data Sheet '!G62,0) -> 6290.42
B55: Capital Work in Progress | C55: =IFERROR('Data Sheet '!B63,0) -> 246.23 | D55: =IFERROR('Data Sheet '!C63,0) -> 358.36 | E55: =IFERROR('Data Sheet '!D63,0) -> 358.36 | F55: =IFERROR('Data Sheet '!E63,0) -> 1741.71 | G55: =IFERROR('Data Sheet '!F63,0) -> 1172.56 | H55: =IFERROR('Data Sheet '!G63,0) -> 506.98
B56: Investments | C56: =IFERROR('Data Sheet '!B64,0) -> 773.98 | D56: =IFERROR('Data Sheet '!C64,0) -> 777.54 | E56: =IFERROR('Data Sheet '!D64,0) -> 777.54 | F56: =IFERROR('Data Sheet '!E64,0) -> 463.87 | G56: =IFERROR('Data Sheet '!F64,0) -> 705.6 | H56: =IFERROR('Data Sheet '!G64,0) -> 705.6
B57: Other Assets | C57: =IFERROR('Data Sheet '!B65,0) -> 4219.25 | D57: =IFERROR('Data Sheet '!C65,0) -> 4799.14 | E57: =IFERROR('Data Sheet '!D65,0) -> 4799.14 | F57: =IFERROR('Data Sheet '!E65,0) -> 4857.23 | G57: =IFERROR('Data Sheet '!F65,0) -> 4972.12 | H57: =IFERROR('Data Sheet '!G65,0) -> 5854.17
...

Sheet Ratio Analysis 
D2: =" Ratio Analysis-"&'Data Sheet '!B1 -> Ratio Analysis-NESTLE INDIA LTD
B3: Year | C3: ='Data Sheet '!B16 -> 44561 | D3: ='Data Sheet '!C16 -> 44926 | E3: ='Data Sheet '!D16 -> 45291 | F3: ='Data Sheet '!E16 -> 45382 | G3: ='Data Sheet '!F16 -> 45747 | H3: ='Data Sheet '!G16 -> 46112 | I3: TREND
B5: Sales Growth | D5: ='Histriocial FS'!D7 -> 0.1462879 | E5: ='Histriocial FS'!E7 -> 0.13193734 | F5: ='Histriocial FS'!F7 -> 0.27541082 | G5: ='Histriocial FS'!G7 -> -0.17185984 | H5: ='Histriocial FS'!H7 -> 0.14617881
B6: EBITDA Growth | D6: ='Histriocial FS'!D18/'Histriocial FS'!C18-1 -> 0.040391309 | E6: ='Histriocial FS'!E18/'Histriocial FS'!D18-1 -> 0.20632492 | F6: ='Histriocial FS'!F18/'Histriocial FS'!E18-1 -> 0.30689624 | G6: ='Histriocial FS'!G18/'Histriocial FS'!F18-1 -> -0.18342769 | H6: ='Histriocial FS'!H18/'Histriocial FS'!G18-1 -> 0.1122601
B7: EBIT Growth | D7: =IFERROR(('Histriocial FS'!D27+'Histriocial FS'!D21)/('Histriocial FS'!C27+'Histriocial FS'!C21)-1,0) -> 0.041590727 | E7: =IFERROR(('Histriocial FS'!E27+'Histriocial FS'!E21)/('Histriocial FS'!D27+'Histriocial FS'!D21)-1,0) -> 0.22365649 | F7: =IFERROR(('Histriocial FS'!F27+'Histriocial FS'!F21)/('Histriocial FS'!E27+'Histriocial FS'!E21)-1,0) -> 0.30511271 | G7: =IFERROR(('Histriocial FS'!G27+'Histriocial FS'!G21)/('Histriocial FS'!F27+'Histriocial FS'!F21)-1,0) -> -0.19789323 | H7: =IFERROR(('Histriocial FS'!H27+'Histriocial FS'!H21)/('Histriocial FS'!G27+'Histriocial FS'!G21)-1,0) -> 0.088934894
B8: EBT Growth | D8: ='Histriocial FS'!D27/'Histriocial FS'!C27-1 -> 0.060278816 | E8: ='Histriocial FS'!E27/'Histriocial FS'!D27-1 -> 0.24584036 | F8: ='Histriocial FS'!F27/'Histriocial FS'!E27-1 -> 0.30771211 | G8: ='Histriocial FS'!G27/'Histriocial FS'!F27-1 -> -0.20165579 | H8: ='Histriocial FS'!H27/'Histriocial FS'!G27-1 -> 0.086440674
B9: Net Profit Growth | D9: =IFERROR('Histriocial FS'!D33/'Histriocial FS'!C33-1,0) -> 0.023520815 | E9: =IFERROR('Histriocial FS'!E33/'Histriocial FS'!D33-1,0) -> 0.26274275 | F9: =IFERROR('Histriocial FS'!F33/'Histriocial FS'!E33-1,0) -> 0.30892386 | G9: =IFERROR('Histriocial FS'!G33/'Histriocial FS'!F33-1,0) -> -0.21500855 | H9: =IFERROR('Histriocial FS'!H33/'Histriocial FS'!G33-1,0) -> 0.14242651
B10: Dividend Growth | D10: =IFERROR('Histriocial FS'!D41/'Histriocial FS'!C41-1,0) -> 0.1 | E10: =IFERROR('Histriocial FS'!E41/'Histriocial FS'!D41-1,0) -> -0.20908997 | F10: =IFERROR('Histriocial FS'!F41/'Histriocial FS'!E41-1,0) -> 0.85028222 | G10: =IFERROR('Histriocial FS'!G41/'Histriocial FS'!F41-1,0) -> -0.1614896 | H10: =IFERROR('Histriocial FS'!H41/'Histriocial FS'!G41-1,0) -> -0.11115721
B12: Gross Margin | C12: =IFERROR('Histriocial FS'!C13,0) -> 0.7298827 | D12: =IFERROR('Histriocial FS'!D13,0) -> 0.65304793 | E12: =IFERROR('Histriocial FS'!E13,0) -> 0.86019302 | F12: =IFERROR('Histriocial FS'!F13,0) -> 0.7298521 | G12: =IFERROR('Histriocial FS'!G13,0) -> 0.72768339 | H12: =IFERROR('Histriocial FS'!H13,0) -> 0.69909097
B13: EBITDA Margin | C13: =IFERROR('Histriocial FS'!C19,0) -> 0.24167282 | D13: =IFERROR('Histriocial FS'!D19,0) -> 0.21934656 | E13: =IFERROR('Histriocial FS'!E19,0) -> 0.23376137 | F13: =IFERROR('Histriocial FS'!F19,0) -> 0.23953211 | G13: =IFERROR('Histriocial FS'!G19,0) -> 0.23618622 | H13: =IFERROR('Histriocial FS'!H19,0) -> 0.22919679
B14: EBIT margin | C14: =IFERROR(SUM('Histriocial FS'!C27,'Histriocial FS'!C21)/'Histriocial FS'!C6,0) -> 0.21514607 | D14: =IFERROR(SUM('Histriocial FS'!D27,'Histriocial FS'!D21)/'Histriocial FS'!D6,0) -> 0.19549552 | E14: =IFERROR(SUM('Histriocial FS'!E27,'Histriocial FS'!E21)/'Histriocial FS'!E6,0) -> 0.21133622 | F14: =IFERROR(SUM('Histriocial FS'!F27,'Histriocial FS'!F21)/'Histriocial FS'!F6,0) -> 0.21625784 | G14: =IFERROR(SUM('Histriocial FS'!G27,'Histriocial FS'!G21)/'Histriocial FS'!G6,0) -> 0.20945957 | H14: =IFERROR(SUM('Histriocial FS'!H27,'Histriocial FS'!H21)/'Histriocial FS'!H6,0) -> 0.19899847
B15: EBT Margin | C15: =IFERROR('Histriocial FS'!C28,0) -> 0.20146412 | D15: =IFERROR('Histriocial FS'!D28,0) -> 0.18634772 | E15: =IFERROR('Histriocial FS'!E28,0) -> 0.20509926 | F15: =IFERROR('Histriocial FS'!F28,0) -> 0.21029364 | G15: =IFERROR('Histriocial FS'!G28,0) -> 0.20272741 | H15: =IFERROR('Histriocial FS'!H28,0) -> 0.19216138
B16: Net Profit Margin | C16: =IFERROR('Histriocial FS'!C34,0) -> 0.15133655 | D16: =IFERROR('Histriocial FS'!D34,0) -> 0.13512845 | E16: =IFERROR('Histriocial FS'!E34,0) -> 0.15074374 | F16: =IFERROR('Histriocial FS'!F34,0) -> 0.15470472 | G16: =IFERROR('Histriocial FS'!G34,0) -> 0.14664412 | H16: =IFERROR('Histriocial FS'!H34,0) -> 0.14616405
B18: Sales Exp% Sales | C18: =IFERROR('Histriocial FS'!C16,0) -> 0.1802533 | D18: =IFERROR('Histriocial FS'!D16,0) -> 0.17571031 | E18: =IFERROR('Histriocial FS'!E16,0) -> 0.22866001 | F18: =IFERROR('Histriocial FS'!F16,0) -> 0.18238379 | G18: =IFERROR('Histriocial FS'!G16,0) -> 0.18500403 | H18: =IFERROR('Histriocial FS'!H16,0) -> 0.1822532
B19: Depreciation% Sales | C19: =IFERROR('Histriocial FS'!C25,0) -> 0.045888172 | D19: =IFERROR('Histriocial FS'!D25,0) -> 0.039426906 | E19: =IFERROR('Histriocial FS'!E25,0) -> 0.041715093 | F19: =IFERROR('Histriocial FS'!F25,0) -> 0.040261046 | G19: =IFERROR('Histriocial FS'!G25,0) -> 0.046175187 | H19: =IFERROR('Histriocial FS'!H25,0) -> 0.051309691
B20: Operationg income %Sales | C20: =C14 -> 0.21514607 | D20: =D14 -> 0.19549552 | E20: =E14 -> 0.21133622 | F20: =F14 -> 0.21625784 | G20: =G14 -> 0.20945957 | H20: =H14 -> 0.19899847
B22: Return on Capital Employed | C22: =IFERROR(('Histriocial FS'!C18-'Histriocial FS'!C24)/(SUM('Histriocial FS'!C48:C50)),0) -> 1.4331719 | D22: =IFERROR(('Histriocial FS'!D18-'Histriocial FS'!D24)/SUM('Histriocial FS'!D48:D50),0) -> 1.2101301 | E22: =IFERROR(('Histriocial FS'!E18-'Histriocial FS'!E24)/SUM('Histriocial FS'!E48:E50),0) -> 1.4807835 | F22: =IFERROR(('Histriocial FS'!F18-'Histriocial FS'!F24)/SUM('Histriocial FS'!F48:F50),0) -> 1.4314162 | G22: =IFERROR(('Histriocial FS'!G18-'Histriocial FS'!G24)/SUM('Histriocial FS'!G48:G50),0) -> 0.80079674 | H22: =IFERROR(('Histriocial FS'!H18-'Histriocial FS'!H24)/SUM('Histriocial FS'!H48:H50),0) -> 0.80087079
B23: Retained Earning % | C23: ='Histriocial FS'!C44 -> 0.13555288 | D23: ='Histriocial FS'!D44 -> 0.070959943 | E23: ='Histriocial FS'!E44 -> 0.4181023 | F23: ='Histriocial FS'!F44 -> 0.17730699 | G23: ='Histriocial FS'!G44 -> 0.12121764 | H23: ='Histriocial FS'!H44 -> 0.31628043
B24: Return on Equity% | C24: =IFERROR('Histriocial FS'!C33/SUM('Histriocial FS'!C48:C49),0) -> 1.1461225 | D24: =IFERROR('Histriocial FS'!D33/SUM('Histriocial FS'!D48:D49),0) -> 0.92846774 | E24: =IFERROR('Histriocial FS'!E33/SUM('Histriocial FS'!E48:E49),0) -> 1.1724159 | F24: =IFERROR('Histriocial FS'!F33/SUM('Histriocial FS'!F48:F49),0) -> 1.1295942 | G24: =IFERROR('Histriocial FS'!G33/SUM('Histriocial FS'!G48:G49),0) -> 0.71953657 | H24: =IFERROR('Histriocial FS'!H33/SUM('Histriocial FS'!H48:H49),0) -> 0.63744905
B25: Self Sustained Growth Rate | C25: =C24*C23 -> 0.15536021 | D25: =D24*D23 -> 0.065884018 | E25: =E24*E23 -> 0.49018978 | F25: =F24*F23 -> 0.20028495 | G25: =G24*G23 -> 0.087220529 | H25: =H24*H23 -> 0.20161266
B26: Interest Coverage ratio | C26: =('Histriocial FS'!C18-'Histriocial FS'!C24)/'Histriocial FS'!C21 -> 15.724812 | D26: =('Histriocial FS'!D18-'Histriocial FS'!D24)/'Histriocial FS'!D21 -> 21.370771 | E26: =('Histriocial FS'!E18-'Histriocial FS'!E24)/'Histriocial FS'!E21 -> 33.884483 | F26: =('Histriocial FS'!F18-'Histriocial FS'!F24)/'Histriocial FS'!F21 -> 36.259331 | G26: =('Histriocial FS'!G18-'Histriocial FS'!G24)/'Histriocial FS'!G21 -> 31.113309 | H26: =('Histriocial FS'!H18-'Histriocial FS'!H24)/'Histriocial FS'!H21 -> 29.105742
B28: Debtor Turnover Ratio | C28: ='Histriocial FS'!C6/'Histriocial FS'!C60 -> 88.814786 | D28: ='Histriocial FS'!D6/'Histriocial FS'!D60 -> 88.055448 | E28: ='Histriocial FS'!E6/'Histriocial FS'!E60 -> 99.67325 | F28: ='Histriocial FS'!F6/'Histriocial FS'!F60 -> 81.188478 | G28: ='Histriocial FS'!G6/'Histriocial FS'!G60 -> 55.628693 | H28: ='Histriocial FS'!H6/'Histriocial FS'!H60 -> 70.278326
B29: Creditor Turnover ratio | C29: ='Histriocial FS'!C6/'Histriocial FS'!C51 -> 2.4480784 | D29: ='Histriocial FS'!D6/'Histriocial FS'!D51 -> 2.7039246 | E29: ='Histriocial FS'!E6/'Histriocial FS'!E51 -> 3.0606732 | F29: ='Histriocial FS'!F6/'Histriocial FS'!F51 -> 3.5675891 | G29: ='Histriocial FS'!G6/'Histriocial FS'!G51 -> 2.8695846 | H29: ='Histriocial FS'!H6/'Histriocial FS'!H51 -> 3.0451473
B30: Inventory Turnover ratio | C30: =IFERROR('Histriocial FS'!C6/'Histriocial FS'!C61,0) -> 9.2553857 | D30: =IFERROR('Histriocial FS'!D6/'Histriocial FS'!D61,0) -> 8.7604847 | E30: =IFERROR('Histriocial FS'!E6/'Histriocial FS'!E61,0) -> 9.9163197 | F30: =IFERROR('Histriocial FS'!F6/'Histriocial FS'!F61,0) -> 11.675293 | G30: =IFERROR('Histriocial FS'!G6/'Histriocial FS'!G61,0) -> 7.0879185 | H30: =IFERROR('Histriocial FS'!H6/'Histriocial FS'!H61,0) -> 9.0123072
B31: Fixed Asset Turnover ratio | C31: =IFERROR('Histriocial FS'!C6/'Histriocial FS'!C54,0) -> 4.9222752 | D31: =IFERROR('Histriocial FS'!D6/'Histriocial FS'!D54,0) -> 5.5514538 | E31: =IFERROR('Histriocial FS'!E6/'Histriocial FS'!E54,0) -> 6.2838979 | F31: =IFERROR('Histriocial FS'!F6/'Histriocial FS'!F54,0) -> 7.0497479 | G31: =IFERROR('Histriocial FS'!G6/'Histriocial FS'!G54,0) -> 3.6907197 | H31: =IFERROR('Histriocial FS'!H6/'Histriocial FS'!H54,0) -> 3.6809307
B32: Capital Turnover ratio | C32: =IFERROR('Histriocial FS'!C6/SUM('Histriocial FS'!C48:C49),0) -> 7.5733361 | D32: =IFERROR('Histriocial FS'!D6/SUM('Histriocial FS'!D48:D49),0) -> 6.8710012 | E32: =IFERROR('Histriocial FS'!E6/SUM('Histriocial FS'!E48:E49),0) -> 7.7775428 | F32: =IFERROR('Histriocial FS'!F6/SUM('Histriocial FS'!F48:F49),0) -> 7.3016142 | G32: =IFERROR('Histriocial FS'!G6/SUM('Histriocial FS'!G48:G49),0) -> 4.9066854 | H32: =IFERROR('Histriocial FS'!H6/SUM('Histriocial FS'!H48:H49),0) -> 4.3611892
B34: Debtor Days | C34: =IFERROR(365/C28,0) -> 4.1096761 | D34: =IFERROR(365/D28,0) -> 4.1451155 | E34: =IFERROR(365/E28,0) -> 3.6619655 | F34: =IFERROR(365/F28,0) -> 4.4957118 | G34: =IFERROR(365/G28,0) -> 6.5613621 | H34: =IFERROR(365/H28,0) -> 5.1936354
B35: Payable Days | C35: =IFERROR(365/C29,0) -> 149.09653 | D35: =IFERROR(365/D29,0) -> 134.98897 | E35: =IFERROR(365/E29,0) -> 119.25481 | F35: =IFERROR(365/F29,0) -> 102.30999 | G35: =IFERROR(365/G29,0) -> 127.19611 | H35: =IFERROR(365/H29,0) -> 119.86284
B36: Inventory Days | C36: =IFERROR(365/C30,0) -> 39.436498 | D36: =IFERROR(365/D30,0) -> 41.664362 | E36: =IFERROR(365/E30,0) -> 36.80801 | F36: =IFERROR(365/F30,0) -> 31.262599 | G36: =IFERROR(365/G30,0) -> 51.496078 | H36: =IFERROR(365/H30,0) -> 40.500173
B37: Cash Conversion Cycle | C37: =SUM(C36,C34)-C35 -> -105.55036 | D37: =SUM(D36,D34)-D35 -> -89.179494 | E37: =SUM(E36,E34)-E35 -> -78.784833 | F37: =SUM(F36,F34)-F35 -> -66.551677 | G37: =SUM(G36,G34)-G35 -> -69.13867 | H37: =SUM(H36,H34)-H35 -> -74.169029

Sheet Data Sheet 
A1: COMPANY NAME | B1: NESTLE INDIA LTD | E1: =IF(B2<>B3, "A NEW VERSION OF THE WORKSHEET IS AVAILABLE", "")
A2: LATEST VERSION | B2: 2.1 | E2: PLEASE DO NOT MAKE ANY CHANGES TO THIS SHEET
A3: CURRENT VERSION | B3: 2.1
A5: META
A6: Number of shares | B6: =IF(B9>0, B9/B8, 0) -> 192.82477
A7: Face Value | B7: 1
A8: Current Price | B8: 1459.8
A9: Market Capitalization | B9: 281485.6
A15: PROFIT & LOSS
A16: Report Date | B16: 44561 | C16: 44926 | D16: 45291 | E16: 45382 | F16: 45747 | G16: 46112
A17: Sales | B17: 14740.59 | C17: 16896.96 | D17: 19126.3 | E17: 24393.89 | F17: 20201.56 | G17: 23154.6
A18: Raw Material Cost | B18: 5301.26 | C18: 6660.42 | D18: 8472.72 | E18: 9201.11 | F18: 7646.63 | G18: 9113.96
A19: Change in Inventory | B19: 67.59 | C19: 250.27 | D19: 40.01 | E19: 45.68 | F19: 139.66 | G19: 168.23
A20: Power and Fuel | B20: 408.06 | C20: 572.61 | E20: 674.83 | F20: 541.42 | G20: 587.21
A21: Other Mfr. Exp | B21: 1349.48 | C21: 1603.48 | E21: 1935.4 | F21: 1582.45 | G21: 1816.29
A22: Employee Cost | B22: 1529.94 | C22: 1635.46 | D22: 1849.18 | E22: 2336.06 | F22: 2062.02 | G22: 2278.41
A23: Selling and admin | B23: 2902.12 | C23: 3192.15 | E23: 4837.58 | F23: 4126.54 | G23: 4780.9
A24: Other Expenses | B24: -245.08 | C24: -223.18 | D24: 4373.42 | E24: -388.53 | F24: -389.17 | G24: -560.9
A25: Other Income | B25: -112.38 | C25: 107.26 | D25: 115.5 | E25: 158.99 | F25: 352.06 | G25: 160.23
A26: Depreciation | B26: 391.02 | C26: 403.01 | D26: 428.91 | E26: 567.75 | F26: 539.92 | G26: 699.23
A27: Interest | B27: 201.68 | C27: 154.57 | D27: 119.29 | E27: 145.49 | F27: 136 | G27: 158.31
A28: Profit before tax | B28: 2857.32 | C28: 3255.97 | D28: 4038.29 | E28: 5288.87 | F28: 4447.47 | G28: 4609.65
A29: Tax | B29: 738.91 | C29: 865.45 | D29: 1039.62 | E29: 1356.03 | F29: 1132.97 | G29: 1065.05
A30: Net profit | B30: 2118.41 | C30: 2390.52 | D30: 2998.67 | E30: 3932.84 | F30: 3314.5 | G30: 3544.6
A31: Dividend Amount | B31: 1928.4 | C31: 2121.24 | D31: 1677.71 | E31: 3104.72 | F31: 2603.34 | G31: 2313.96
A40: Quarters
A41: Report Date | B41: 45291 | C41: 45382 | D41: 45473 | E41: 45565 | F41: 45657 | G41: 45747 | H41: 45838 | I41: 45930 | J41: 46022 | K41: 46112
A42: Sales | B42: 4600.42 | C42: 5267.59 | D42: 4813.95 | E42: 5104 | F42: 4779.73 | G42: 5503.88 | H42: 5096.16 | I42: 5643.61 | J42: 5667.04 | K42: 6747.79
A43: Expenses | B43: 3505.3 | C43: 3917.54 | D43: 3699.62 | E43: 3936.27 | F43: 3677.04 | G43: 4115.58 | H43: 3995.9 | I43: 4406.97 | J43: 4466.09 | K43: 4976.19
A44: Other Income | B44: -77 | C44: 36.83 | D44: 39.12 | E44: 297.68 | F44: 4.44 | G44: 9.1 | H44: 4.04 | I44: 1.64 | J44: 169.78 | K44: -17.72
A45: Depreciation | B45: 108.69 | C45: 110.1 | D45: 112.71 | E45: 121.6 | F45: 150.27 | G45: 155.34 | H45: 156.94 | I45: 163.35 | J45: 174.41 | K45: 204.53
A46: Interest | B46: 22.95 | C46: 26.2 | D46: 31.68 | E46: 32.22 | F46: 34.6 | G46: 37.5 | H46: 46.89 | I46: 46.41 | J46: 28.25 | K46: 36.76
A47: Profit before tax | B47: 886.48 | C47: 1250.58 | D47: 1009.06 | E47: 1311.59 | F47: 922.26 | G47: 1204.56 | H47: 900.47 | I47: 1028.52 | J47: 1168.07 | K47: 1512.59
A48: Tax | B48: 230.87 | C48: 316.41 | D48: 262.46 | E48: 325.23 | F48: 226.13 | G48: 319.15 | H48: 241.24 | I48: 275.32 | J48: 150.01 | K48: 398.48
A49: Net profit | B49: 655.61 | C49: 934.17 | D49: 746.6 | E49: 986.36 | F49: 696.13 | G49: 885.41 | H49: 659.23 | I49: 753.2 | J49: 1018.06 | K49: 1114.11
A50: Operating Profit | B50: 1095.12 | C50: 1350.05 | D50: 1114.33 | E50: 1167.73 | F50: 1102.69 | G50: 1388.3 | H50: 1100.26 | I50: 1236.64 | J50: 1200.95 | K50: 1771.6
A55: BALANCE SHEET
A56: Report Date | B56: 44561 | C56: 44926 | D56: 45291 | E56: 45382 | F56: 45747 | G56: 46112
A57: Equity Share Capital | B57: 96.42 | C57: 96.42 | D57: 96.42 | E57: 96.42 | F57: 96.42 | G57: 192.83
A58: Reserves | B58: 1849.96 | C58: 2362.75 | D58: 2362.75 | E58: 3244.47 | F58: 4020.73 | G58: 5116.41
...

Sheet Cash flow
B2: Standalone Figures in Rs. Crores / View Consolidated
C3: 44531 | D3: 44896 | E3: 45261 | F3: 45352 | G3: 45717 | H3: 46082
B4: Cash from Operating Activity - | C4: 2236 | D4: 2737 | E4: 3392 | F4: 4175 | G4: 2935 | H4: 5048
B5: Profit from operations | C5: 3136 | D5: 3609 | E5: 4388 | F5: 5722 | G5: 4672 | H5: 5326
B6: Receivables | C6: -2 | D6: -28 | E6: -11 | F6: -109 | G6: -70 | H6: 34
B7: Inventory | C7: -169 | D7: -336 | E7: 56 | F7: -161 | G7: -767 | H7: 281
B8: Payables | C8: 217 | D8: 178 | E8: 68 | F8: 310 | G8: 134 | H8: 588
B9: Loans Advances | C9: -40 | D9: -30 | E9: -30 | F9: -21 | G9: -199 | H9: -73
B10: Operating borrowings | C10: 0 | D10: 0 | E10: 0 | F10: 0 | G10: 0 | H10: 0
B11: Other WC items | C11: -179 | D11: 185 | E11: -19 | F11: -268 | G11: 155 | H11: -37
B12: Working capital changes | C12: -172 | D12: -30 | E12: 63 | F12: -249 | G12: -747 | H12: 793
B13: Direct taxes | C13: -729 | D13: -841 | E13: -1059 | F13: -1299 | G13: -990 | H13: -1071
B14: Cash from Investing Activity - | C14: -1920 | D14: -392 | E14: -927 | F14: -1237 | G14: -1811 | H14: -624
B15: Fixed assets purchased | C15: -735 | D15: -550 | E15: -1371 | F15: -1883 | G15: -2009 | H15: -830
... B33: CFO/OP | C33: 0.83 | D33: 0.97 | E33: 1 | F33: 0.94 | G33: 0.82 | H33: 1.15
