Workbook
Name IQ_CH: 110000
Name IQ_CQ: 5000
Name IQ_CY: 10000
Name IQ_DAILY: 500000
Name IQ_FH: 100000
Name IQ_FQ: 500
Name IQ_FY: 1000
Name IQ_LTM: 2000
Name IQ_MONTH: 15000
Name IQ_NTM: 6000
Name IQ_WEEK: 50000
Name IQ_YTD: 3000
Name UPDATE: 'Data Sheet1'!$E$1

Sheet Financials>

Sheet Income Statement
H2: Figures in Rs. Crores | Q2: Figures in Rs. Crores
D3: ="Historical Financial Statement - "&'Data Sheet1'!B1 -> Historical Financial Statement - HINDUSTAN UNILEVER LTD | N3: ="Historical Financial Statement - "&'Data Sheet2'!B1 -> Historical Financial Statement - NESTLE INDIA LTD
B4: Years | C4: ='Data Sheet1'!F16 -> 44286 | D4: ='Data Sheet1'!G16 -> 44651 | E4: ='Data Sheet1'!H16 -> 45016 | F4: ='Data Sheet1'!I16 -> 45382 | G4: ='Data Sheet1'!J16 -> 45747 | H4: ='Data Sheet1'!K16 -> 46112 | I4: LTM | L4: =C4 -> 44286 | M4: =D4 -> 44651 | N4: =E4 -> 45016 | O4: =F4 -> 45382 | P4: =G4 -> 45747 | Q4: =H4 -> 46112 | R4: =I4 -> LTM
A6: # | B6: Income Statement | L6: # Income Statement
B7: Sales | C7: =IFERROR('Data Sheet1'!F17,0) -> 47028 | D7: =IFERROR('Data Sheet1'!G17,0) -> 52446 | E7: =IFERROR('Data Sheet1'!H17,0) -> 60580 | F7: =IFERROR('Data Sheet1'!I17,0) -> 61896 | G7: =IFERROR('Data Sheet1'!J17,0) -> 61328 | H7: =IFERROR('Data Sheet1'!K17,0) -> 64468 | I7: =IFERROR(SUM('Data Sheet1'!H42:K42),0) -> 65225 | L7: =IFERROR('Data Sheet2'!F17,0) -> 14740.59 | M7: =IFERROR('Data Sheet2'!G17,0) -> 16896.96 | N7: =IFERROR('Data Sheet2'!H17,0) -> 19126.3 | O7: =IFERROR('Data Sheet2'!I17,0) -> 24393.89 | P7: =IFERROR('Data Sheet2'!J17,0) -> 20201.56 | Q7: =IFERROR('Data Sheet2'!K17,0) -> 23154.6 | R7: =IFERROR(SUM('Data Sheet2'!H42:K42),0) -> 23154.6
B8: Sales Growth | D8: =D7/C7-1 -> 0.11520796 | E8: =E7/D7-1 -> 0.15509286 | F8: =F7/E7-1 -> 0.021723341 | G8: =G7/F7-1 -> -0.0091766835 | H8: =H7/G7-1 -> 0.051200104 | I8: =I7/H7-1 -> 0.01174226 | M8: =M7/L7-1 -> 0.1462879 | N8: =N7/M7-1 -> 0.13193734 | O8: =O7/N7-1 -> 0.27541082 | P8: =P7/O7-1 -> -0.17185984 | Q8: =Q7/P7-1 -> 0.14617881 | R8: =R7/Q7-1 -> 0
B10: COGS | C10: =IFERROR(SUM('Data Sheet1'!F18,'Data Sheet1'!F20:F22)-1*'Data Sheet1'!F19,0) -> 25301 | D10: =IFERROR(SUM('Data Sheet1'!G18,'Data Sheet1'!G20:G22)-1*'Data Sheet1'!G19,0) -> 29066 | E10: =IFERROR(SUM('Data Sheet1'!H18,'Data Sheet1'!H20:H22)-1*'Data Sheet1'!H19,0) -> 35381 | F10: =IFERROR(SUM('Data Sheet1'!I18,'Data Sheet1'!I20:I22)-1*'Data Sheet1'!I19,0) -> 33651 | G10: =IFERROR(SUM('Data Sheet1'!J18,'Data Sheet1'!J20:J22)-1*'Data Sheet1'!J19,0) -> 33519 | H10: =IFERROR(SUM('Data Sheet1'!K18,'Data Sheet1'!K20:K22)-1*'Data Sheet1'!K19,0) -> 35634 | I10: =IFERROR(SUM('Data Sheet1'!H43:K43),0) -> 50108 | L10: =IFERROR(SUM('Data Sheet2'!F18,'Data Sheet2'!F20:F22)-1*'Data Sheet2'!F19,0) -> 8521.15 | M10: =IFERROR(SUM('Data Sheet2'!G18,'Data Sheet2'!G20:G22)-1*'Data Sheet2'!G19,0) -> 10221.7 | N10: =IFERROR(SUM('Data Sheet2'!H18,'Data Sheet2'!H20:H22)-1*'Data Sheet2'!H19,0) -> 10281.89 | O10: =IFERROR(SUM('Data Sheet2'!I18,'Data Sheet2'!I20:I22)-1*'Data Sheet2'!I19,0) -> 14101.72 | P10: =IFERROR(SUM('Data Sheet2'!J18,'Data Sheet2'!J20:J22)-1*'Data Sheet2'!J19,0) -> 11692.86 | Q10: =IFERROR(SUM('Data Sheet2'!K18,'Data Sheet2'!K20:K22)-1*'Data Sheet2'!K19,0) -> 13627.64 | R10: =IFERROR(SUM('Data Sheet2'!H43:K43),0) -> 17845.15
B11: COGS % Sales | C11: =C10/C7 -> 0.53799864 | D11: =D10/D7 -> 0.55420814 | E11: =E10/E7 -> 0.58403764 | F11: =F10/F7 -> 0.54367003 | G11: =G10/G7 -> 0.54655296 | H11: =H10/H7 -> 0.55273934 | I11: =I10/I7 -> 0.76823304 | L11: =L10/L7 -> 0.57807388 | M11: =M10/M7 -> 0.60494314 | N11: =N10/N7 -> 0.53757862 | O11: =O10/O7 -> 0.5780841 | P11: =P10/P7 -> 0.57880976 | Q11: =Q10/Q7 -> 0.58855001 | R11: =R10/R7 -> 0.77069567
B13: Gross Profit | C13: =C7-C10 -> 21727 | D13: =D7-D10 -> 23380 | E13: =E7-E10 -> 25199 | F13: =F7-F10 -> 28245 | G13: =G7-G10 -> 27809 | H13: =H7-H10 -> 28834 | I13: =I7-I10 -> 15117 | L13: =L7-L10 -> 6219.44 | M13: =M7-M10 -> 6675.26 | N13: =N7-N10 -> 8844.41 | O13: =O7-O10 -> 10292.17 | P13: =P7-P10 -> 8508.7 | Q13: =Q7-Q10 -> 9526.96 | R13: =R7-R10 -> 5309.45
B14: Gross Margins | C14: =C13/C7 -> 0.46200136 | D14: =D13/D7 -> 0.44579186 | E14: =E13/E7 -> 0.41596236 | F14: =F13/F7 -> 0.45632997 | G14: =G13/G7 -> 0.45344704 | H14: =H13/H7 -> 0.44726066 | I14: =I13/I7 -> 0.23176696 | L14: =L13/L7 -> 0.42192612 | M14: =M13/M7 -> 0.39505686 | N14: =N13/N7 -> 0.46242138 | O14: =O13/O7 -> 0.4219159 | P14: =P13/P7 -> 0.42119024 | Q14: =Q13/Q7 -> 0.41144999 | R14: =R13/R7 -> 0.22930433
B16: Selling & General Expenses | C16: =IFERROR(SUM('Data Sheet1'!F23:F24),0) -> 10101 | D16: =IFERROR(SUM('Data Sheet1'!G23:G24),0) -> 10523 | E16: =IFERROR(SUM('Data Sheet1'!H23:H24),0) -> 11052 | F16: =IFERROR(SUM('Data Sheet1'!I23:I24),0) -> 13586 | G16: =IFERROR(SUM('Data Sheet1'!J23:J24),0) -> 13111 | H16: =IFERROR(SUM('Data Sheet1'!K23:K24),0) -> 13795 | L16: =IFERROR(SUM('Data Sheet2'!F23:F24),0) -> 2657.04 | M16: =IFERROR(SUM('Data Sheet2'!G23:G24),0) -> 2968.97 | N16: =IFERROR(SUM('Data Sheet2'!H23:H24),0) -> 4373.42 | O16: =IFERROR(SUM('Data Sheet2'!I23:I24),0) -> 4449.05 | P16: =IFERROR(SUM('Data Sheet2'!J23:J24),0) -> 3737.37 | Q16: =IFERROR(SUM('Data Sheet2'!K23:K24),0) -> 4220
B17: S&G Exp % Sales | C17: =C16/C7 -> 0.21478694 | D17: =D16/D7 -> 0.20064447 | E17: =E16/E7 -> 0.18243645 | F17: =F16/F7 -> 0.21949722 | G17: =G16/G7 -> 0.21378489 | H17: =H16/H7 -> 0.21398213 | I17: =I16/I7 -> 0 | L17: =L16/L7 -> 0.1802533 | M17: =M16/M7 -> 0.17571031 | N17: =N16/N7 -> 0.22866001 | O17: =O16/O7 -> 0.18238379 | P17: =P16/P7 -> 0.18500403 | Q17: =Q16/Q7 -> 0.1822532 | R17: =R16/R7 -> 0
B19: EBITDA | C19: =C13-C16 -> 11626 | D19: =D13-D16 -> 12857 | E19: =E13-E16 -> 14147 | F19: =F13-F16 -> 14659 | G19: =G13-G16 -> 14698 | H19: =H13-H16 -> 15039 | I19: =IFERROR(SUM('Data Sheet1'!H51:K51),0) -> 19992 | L19: =L13-L16 -> 3562.4 | M19: =M13-M16 -> 3706.29 | N19: =N13-N16 -> 4470.99 | O19: =O13-O16 -> 5843.12 | P19: =P13-P16 -> 4771.33 | Q19: =Q13-Q16 -> 5306.96 | R19: =R13-R16 -> 5309.45
B20: EBITDA Margins | C20: =C19/C7 -> 0.24721443 | D20: =D19/D7 -> 0.24514739 | E20: =E19/E7 -> 0.23352592 | F20: =F19/F7 -> 0.23683275 | G20: =G19/G7 -> 0.23966214 | H20: =H19/H7 -> 0.23327853 | I20: =I19/I7 -> 0.30650824 | L20: =L19/L7 -> 0.24167282 | M20: =M19/M7 -> 0.21934656 | N20: =N19/N7 -> 0.23376137 | O20: =O19/O7 -> 0.23953211 | P20: =P19/P7 -> 0.23618622 | Q20: =Q19/Q7 -> 0.22919679 | R20: =R19/R7 -> 0.22930433
B22: Interest | C22: =IFERROR('Data Sheet1'!F27,0) -> 117 | D22: =IFERROR('Data Sheet1'!G27,0) -> 106 | E22: =IFERROR('Data Sheet1'!H27,0) -> 114 | F22: =IFERROR('Data Sheet1'!I27,0) -> 334 | G22: =IFERROR('Data Sheet1'!J27,0) -> 381 | H22: =IFERROR('Data Sheet1'!K27,0) -> 410 | I22: =IFERROR(SUM('Data Sheet1'!H46:K46),0) -> 415 | L22: =IFERROR('Data Sheet2'!F27,0) -> 201.68 | M22: =IFERROR('Data Sheet2'!G27,0) -> 154.57 | N22: =IFERROR('Data Sheet2'!H27,0) -> 119.29 | O22: =IFERROR('Data Sheet2'!I27,0) -> 145.49 | P22: =IFERROR('Data Sheet2'!J27,0) -> 136 | Q22: =IFERROR('Data Sheet2'!K27,0) -> 158.31 | R22: =IFERROR(SUM('Data Sheet2'!H46:K46),0) -> 158.31
B23: Interest % Sales | C23: =C22/C7 -> 0.0024878796 | D23: =D22/D7 -> 0.0020211265 | E23: =E22/E7 -> 0.0018818092 | F23: =F22/F7 -> 0.0053961484 | G23: =G22/G7 -> 0.0062124967 | H23: =H22/H7 -> 0.0063597444 | I23: =I22/I7 -> 0.006362591 | L23: =L22/L7 -> 0.013681949 | M23: =M22/M7 -> 0.0091477994 | N23: =N22/N7 -> 0.0062369617 | O23: =O22/O7 -> 0.0059641984 | P23: =P22/P7 -> 0.0067321534 | Q23: =Q22/Q7 -> 0.0068370864 | R23: =R22/R7 -> 0.0068370864
B25: Depreciation | C25: =IFERROR('Data Sheet1'!F26,0) -> 1074 | D25: =IFERROR('Data Sheet1'!G26,0) -> 1091 | E25: =IFERROR('Data Sheet1'!H26,0) -> 1137 | F25: =IFERROR('Data Sheet1'!I26,0) -> 1216 | G25: =IFERROR('Data Sheet1'!J26,0) -> 1253 | H25: =IFERROR('Data Sheet1'!K26,0) -> 1333 | I25: =IFERROR(SUM('Data Sheet1'!H45:K45),0) -> 1368 | L25: =IFERROR('Data Sheet2'!F26,0) -> 391.02 | M25: =IFERROR('Data Sheet2'!G26,0) -> 403.01 | N25: =IFERROR('Data Sheet2'!H26,0) -> 428.91 | O25: =IFERROR('Data Sheet2'!I26,0) -> 567.75 | P25: =IFERROR('Data Sheet2'!J26,0) -> 539.92 | Q25: =IFERROR('Data Sheet2'!K26,0) -> 699.23 | R25: =IFERROR(SUM('Data Sheet2'!H45:K45),0) -> 699.23
B26: Depreciation%Sales | C26: =C25/C7 -> 0.022837459 | D26: =D25/D7 -> 0.020802349 | E26: =E25/E7 -> 0.01876857 | F26: =F25/F7 -> 0.019645858 | G26: =G25/G7 -> 0.020431124 | H26: =H25/H7 -> 0.020676925 | I26: =I25/I7 -> 0.020973553 | L26: =L25/L7 -> 0.026526754 | M26: =M25/M7 -> 0.023851036 | N26: =N25/N7 -> 0.022425142 | O26: =O25/O7 -> 0.023274271 | P26: =P25/P7 -> 0.026726649 | Q26: =Q25/Q7 -> 0.030198319 | R26: =R25/R7 -> 0.030198319
B28: Earnings Before Tax | C28: =IFERROR(C19-SUM(C25,C22),0) -> 10435 | D28: =IFERROR(D19-SUM(D25,D22),0) -> 11660 | E28: =IFERROR(E19-SUM(E25,E22),0) -> 12896 | F28: =IFERROR(F19-SUM(F25,F22),0) -> 13109 | G28: =IFERROR(G19-SUM(G25,G22),0) -> 13064 | H28: =IFERROR(H19-SUM(H25,H22),0) -> 13296 | I28: =IFERROR(I19-SUM(I25,I22),0) -> 18209 | L28: =IFERROR(L19-SUM(L25,L22),0) -> 2969.7 | M28: =IFERROR(M19-SUM(M25,M22),0) -> 3148.71 | N28: =IFERROR(N19-SUM(N25,N22),0) -> 3922.79 | O28: =IFERROR(O19-SUM(O25,O22),0) -> 5129.88 | P28: =IFERROR(P19-SUM(P25,P22),0) -> 4095.41 | Q28: =IFERROR(Q19-SUM(Q25,Q22),0) -> 4449.42 | R28: =IFERROR(R19-SUM(R25,R22),0) -> 4451.91
B29: EBT % Sales | C29: =C28/C7 -> 0.22188909 | D29: =D28/D7 -> 0.22232391 | E29: =E28/E7 -> 0.21287554 | F29: =F28/F7 -> 0.21179075 | G29: =G28/G7 -> 0.21301852 | H29: =H28/H7 -> 0.20624186 | I29: =I28/I7 -> 0.2791721 | L29: =L28/L7 -> 0.20146412 | M29: =M28/M7 -> 0.18634772 | N29: =N28/N7 -> 0.20509926 | O29: =O28/O7 -> 0.21029364 | P29: =P28/P7 -> 0.20272741 | Q29: =Q28/Q7 -> 0.19216138 | R29: =R28/R7 -> 0.19226892
B31: Tax | C31: =IFERROR('Data Sheet1'!F29,0) -> 2606 | D31: =IFERROR('Data Sheet1'!G29,0) -> 2987 | E31: =IFERROR('Data Sheet1'!H29,0) -> 3201 | F31: =IFERROR('Data Sheet1'!I29,0) -> 3644 | G31: =IFERROR('Data Sheet1'!J29,0) -> 3748 | H31: =IFERROR('Data Sheet1'!K29,0) -> 3160 | I31: =IFERROR(SUM('Data Sheet1'!H48:K48),0) -> 3169 | L31: =IFERROR('Data Sheet2'!F29,0) -> 738.91 | M31: =IFERROR('Data Sheet2'!G29,0) -> 865.45 | N31: =IFERROR('Data Sheet2'!H29,0) -> 1039.62 | O31: =IFERROR('Data Sheet2'!I29,0) -> 1356.03 | P31: =IFERROR('Data Sheet2'!J29,0) -> 1132.97 | Q31: =IFERROR('Data Sheet2'!K29,0) -> 1065.05 | R31: =IFERROR(SUM('Data Sheet2'!H48:K48),0) -> 1065.05
B32: Effective Tax Rate | C32: =C31/C28 -> 0.24973646 | D32: =D31/D28 -> 0.25617496 | E32: =E31/E28 -> 0.2482165 | F32: =F31/F28 -> 0.27797696 | G32: =G31/G28 -> 0.28689528 | H32: =H31/H28 -> 0.23766546 | I32: =I31/I28 -> 0.17403482 | L32: =L31/L28 -> 0.24881638 | M32: =M31/M28 -> 0.27485859 | N32: =N31/N28 -> 0.26502056 | O32: =O31/O28 -> 0.26433952 | P32: =P31/P28 -> 0.27664385 | Q32: =Q31/Q28 -> 0.23936828 | R32: =R31/R28 -> 0.2392344
B34: Net Profit | C34: =IFERROR(C28-C31,0) -> 7829 | D34: =IFERROR(D28-D31,0) -> 8673 | E34: =IFERROR(E28-E31,0) -> 9695 | F34: =IFERROR(F28-F31,0) -> 9465 | G34: =IFERROR(G28-G31,0) -> 9316 | H34: =IFERROR(H28-H31,0) -> 10136 | I34: =IFERROR(I28-I31,0) -> 15040 | L34: =IFERROR(L28-L31,0) -> 2230.79 | M34: =IFERROR(M28-M31,0) -> 2283.26 | N34: =IFERROR(N28-N31,0) -> 2883.17 | O34: =IFERROR(O28-O31,0) -> 3773.85 | P34: =IFERROR(P28-P31,0) -> 2962.44 | Q34: =IFERROR(Q28-Q31,0) -> 3384.37 | R34: =IFERROR(R28-R31,0) -> 3386.86
B35: Net Margins | C35: =C34/C7 -> 0.16647529 | D35: =D34/D7 -> 0.16537009 | E35: =E34/E7 -> 0.16003632 | F35: =F34/F7 -> 0.1529178 | G35: =G34/G7 -> 0.15190451 | H35: =H34/H7 -> 0.15722529 | I35: =I34/I7 -> 0.23058643 | L35: =L34/L7 -> 0.15133655 | M35: =M34/M7 -> 0.13512845 | N35: =N34/N7 -> 0.15074374 | O35: =O34/O7 -> 0.15470472 | P35: =P34/P7 -> 0.14664412 | Q35: =Q34/Q7 -> 0.14616405 | R35: =R34/R7 -> 0.14627158
B37: No of Equity Shares | C37: =IFERROR('Data Sheet1'!F93,0) -> 234.96 | D37: =IFERROR('Data Sheet1'!G93,0) -> 234.96 | E37: =IFERROR('Data Sheet1'!H93,0) -> 234.96 | F37: =IFERROR('Data Sheet1'!I93,0) -> 234.96 | G37: =IFERROR('Data Sheet1'!J93,0) -> 234.96 | H37: =IFERROR('Data Sheet1'!K93,0) -> 234.96 | I37: =H37 -> 234.96 | L37: ='Data Sheet2'!F93 -> 192.8 | M37: ='Data Sheet2'!G93 -> 192.8 | N37: ='Data Sheet2'!H93 -> 192.8 | O37: ='Data Sheet2'!I93 -> 192.83 | P37: ='Data Sheet2'!J93 -> 192.83 | Q37: ='Data Sheet2'!K93 -> 192.83 | R37: =Q37 -> 192.83
B39: Earnings per Share | C39: =IFERROR(C34/C37,0) -> 33.320565 | D39: =IFERROR(D34/D37,0) -> 36.912666 | E39: =IFERROR(E34/E37,0) -> 41.262343 | F39: =IFERROR(F34/F37,0) -> 40.283453 | G39: =IFERROR(G34/G37,0) -> 39.649302 | H39: =IFERROR(H34/H37,0) -> 43.139258 | I39: =IFERROR(I34/I37,0) -> 64.010895 | L39: =IFERROR(L34/L37,0) -> 11.570488 | M39: =IFERROR(M34/M37,0) -> 11.842635 | N39: =IFERROR(N34/N37,0) -> 14.954201 | O39: =IFERROR(O34/O37,0) -> 19.570866 | P39: =IFERROR(P34/P37,0) -> 15.362962 | Q39: =IFERROR(Q34/Q37,0) -> 17.551055 | R39: =IFERROR(R34/R37,0) -> 17.563968
B40: EPS Growth % | D40: =IFERROR(D39/C39-1,0) -> 0.10780432 | E40: =IFERROR(E39/D39-1,0) -> 0.11783697 | F40: =IFERROR(F39/E39-1,0) -> -0.023723569 | G40: =IFERROR(G39/F39-1,0) -> -0.015742208 | H40: =IFERROR(H39/G39-1,0) -> 0.08802061 | I40: =IFERROR(I39/H39-1,0) -> 0.48382005 | M40: =IFERROR(M39/L39-1,0) -> 0.023520815 | N40: =IFERROR(N39/M39-1,0) -> 0.26274275 | O40: =IFERROR(O39/N39-1,0) -> 0.30872022 | P40: =IFERROR(P39/O39-1,0) -> -0.21500855 | Q40: =IFERROR(Q39/P39-1,0) -> 0.14242651 | R40: =IFERROR(R39/Q39-1,0) -> 0.00073573516
B42: Dividend per Share | C42: =IFERROR('Data Sheet1'!F31/'Income Statement'!C37,0) -> 40.506895 | D42: =IFERROR('Data Sheet1'!G31/'Income Statement'!D37,0) -> 34.005788 | E42: =IFERROR('Data Sheet1'!H31/'Income Statement'!E37,0) -> 39.006639 | F42: =IFERROR('Data Sheet1'!I31/'Income Statement'!F37,0) -> 42.00715 | G42: =IFERROR('Data Sheet1'!J31/'Income Statement'!G37,0) -> 53.009023 | H42: =IFERROR('Data Sheet1'!K31/'Income Statement'!H37,0) -> 41.00698 | I42: =IFERROR('Data Sheet1'!L31/'Income Statement'!I37,0) -> 0 | L42: =IFERROR('Data Sheet2'!F31/'Income Statement'!L37,0) -> 10.002075 | M42: =IFERROR('Data Sheet2'!G31/'Income Statement'!M37,0) -> 11.002282 | N42: =IFERROR('Data Sheet2'!H31/'Income Statement'!N37,0) -> 8.7018154 | O42: =IFERROR('Data Sheet2'!I31/'Income Statement'!O37,0) -> 16.100814 | P42: =IFERROR('Data Sheet2'!J31/'Income Statement'!P37,0) -> 13.5007 | Q42: =IFERROR('Data Sheet2'!K31/'Income Statement'!Q37,0) -> 12 | R42: =IFERROR('Data Sheet2'!L31/'Income Statement'!R37,0) -> 0
B43: Dividend payout ratio | C43: =IFERROR(C42/C39,0) -> 1.2156725 | D43: =IFERROR(D42/D39,0) -> 0.92124986 | E43: =IFERROR(E42/E39,0) -> 0.94533265 | F43: =IFERROR(F42/F39,0) -> 1.0427892 | G43: =IFERROR(G42/G39,0) -> 1.3369472 | H43: =IFERROR(H42/H39,0) -> 0.95057222 | I43: =IFERROR(I42/I39,0) -> 0 | L43: =IFERROR(L42/L39,0) -> 0.86444712 | M43: =IFERROR(M42/M39,0) -> 0.92904006 | N43: =IFERROR(N42/N39,0) -> 0.5818977 | O43: =IFERROR(O42/O39,0) -> 0.82269301 | P43: =IFERROR(P42/P39,0) -> 0.87878236 | Q43: =IFERROR(Q42/Q39,0) -> 0.68371957 | R43: =IFERROR(R42/R39,0) -> 0
B45: Retained Earnings | C45: =IFERROR(IF(C39>C42,1-C43,0),0) -> 0 | D45: =IFERROR(IF(D39>D42,1-D43,0),0) -> 0.078750144 | E45: =IFERROR(IF(E39>E42,1-E43,0),0) -> 0.054667354 | F45: =IFERROR(IF(F39>F42,1-F43,0),0) -> 0 | G45: =IFERROR(IF(G39>G42,1-G43,0),0) -> 0 | H45: =IFERROR(IF(H39>H42,1-H43,0),0) -> 0.049427782 | I45: =IFERROR(IF(I39>I42,1-I43,0),0) -> 1 | L45: =IFERROR(IF(L39>L42,1-L43,0),0) -> 0.13555288 | M45: =IFERROR(IF(M39>M42,1-M43,0),0) -> 0.070959943 | N45: =IFERROR(IF(N39>N42,1-N43,0),0) -> 0.4181023 | O45: =IFERROR(IF(O39>O42,1-O43,0),0) -> 0.17730699 | P45: =IFERROR(IF(P39>P42,1-P43,0),0) -> 0.12121764 | Q45: =IFERROR(IF(Q39>Q42,1-Q43,0),0) -> 0.31628043 | R45: =IFERROR(IF(R39>R42,1-R43,0),0) -> 1

Sheet Balance Sheet
A2: # | D2: ="Balance Sheet - "&'Data Sheet1'!B1 -> Balance Sheet - HINDUSTAN UNILEVER LTD | L2: ="Balance Sheet - "&'Data Sheet2'!B1 -> Balance Sheet - NESTLE INDIA LTD
B3: Years | C3: ='Data Sheet1'!F16 -> 44286 | D3: ='Data Sheet1'!G16 -> 44651 | E3: ='Data Sheet1'!H16 -> 45016 | F3: ='Data Sheet1'!I16 -> 45382 | G3: ='Data Sheet1'!J16 -> 45747 | H3: ='Data Sheet1'!K16 -> 46112 | K3: =C3 -> 44286 | L3: =D3 -> 44651 | M3: =E3 -> 45016 | N3: =F3 -> 45382 | O3: =G3 -> 45747 | P3: =H3 -> 46112
B5: Equity Share Capital | C5: =IFERROR('Data Sheet1'!F57,0) -> 235 | D5: =IFERROR('Data Sheet1'!G57,0) -> 235 | E5: =IFERROR('Data Sheet1'!H57,0) -> 235 | F5: =IFERROR('Data Sheet1'!I57,0) -> 235 | G5: =IFERROR('Data Sheet1'!J57,0) -> 235 | H5: =IFERROR('Data Sheet1'!K57,0) -> 235 | K5: =IFERROR('Data Sheet2'!F57,0) -> 96.42 | L5: =IFERROR('Data Sheet2'!G57,0) -> 96.42 | M5: =IFERROR('Data Sheet2'!H57,0) -> 96.42 | N5: =IFERROR('Data Sheet2'!I57,0) -> 96.42 | O5: =IFERROR('Data Sheet2'!J57,0) -> 96.42 | P5: =IFERROR('Data Sheet2'!K57,0) -> 192.83
B6: Reserves | C6: =IFERROR('Data Sheet1'!F58,0) -> 47439 | D6: =IFERROR('Data Sheet1'!G58,0) -> 48826 | E6: =IFERROR('Data Sheet1'!H58,0) -> 50069 | F6: =IFERROR('Data Sheet1'!I58,0) -> 50983 | G6: =IFERROR('Data Sheet1'!J58,0) -> 49167 | H6: =IFERROR('Data Sheet1'!K58,0) -> 48504 | K6: =IFERROR('Data Sheet2'!F58,0) -> 1849.96 | L6: =IFERROR('Data Sheet2'!G58,0) -> 2362.75 | M6: =IFERROR('Data Sheet2'!H58,0) -> 2362.75 | N6: =IFERROR('Data Sheet2'!I58,0) -> 3244.47 | O6: =IFERROR('Data Sheet2'!J58,0) -> 4020.73 | P6: =IFERROR('Data Sheet2'!K58,0) -> 5116.41
B7: Borrowings | C7: =IFERROR('Data Sheet1'!F59,0) -> 0 | D7: =IFERROR('Data Sheet1'!G59,0) -> 1043 | E7: =IFERROR('Data Sheet1'!H59,0) -> 1219 | F7: =IFERROR('Data Sheet1'!I59,0) -> 1484 | G7: =IFERROR('Data Sheet1'!J59,0) -> 1648 | H7: =IFERROR('Data Sheet1'!K59,0) -> 1478 | K7: =IFERROR('Data Sheet2'!F59,0) -> 266.46 | L7: =IFERROR('Data Sheet2'!G59,0) -> 270.52 | M7: =IFERROR('Data Sheet2'!H59,0) -> 270.52 | N7: =IFERROR('Data Sheet2'!I59,0) -> 344.53 | O7: =IFERROR('Data Sheet2'!J59,0) -> 1166.85 | P7: =IFERROR('Data Sheet2'!K59,0) -> 444.16
B8: Other Liabilities | C8: =IFERROR('Data Sheet1'!F60,0) -> 21066 | D8: =IFERROR('Data Sheet1'!G60,0) -> 20402 | E8: =IFERROR('Data Sheet1'!H60,0) -> 21554 | F8: =IFERROR('Data Sheet1'!I60,0) -> 25787 | G8: =IFERROR('Data Sheet1'!J60,0) -> 28813 | H8: =IFERROR('Data Sheet1'!K60,0) -> 29521 | K8: =IFERROR('Data Sheet2'!F60,0) -> 6021.29 | L8: =IFERROR('Data Sheet2'!G60,0) -> 6249.05 | M8: =IFERROR('Data Sheet2'!H60,0) -> 6249.05 | N8: =IFERROR('Data Sheet2'!I60,0) -> 6837.64 | O8: =IFERROR('Data Sheet2'!J60,0) -> 7039.89 | P8: =IFERROR('Data Sheet2'!K60,0) -> 7603.77
B9: Total Liabilities | C9: =SUM(C5:C8,0) -> 68740 | D9: =SUM(D5:D8,0) -> 70506 | E9: =SUM(E5:E8,0) -> 73077 | F9: =SUM(F5:F8,0) -> 78489 | G9: =SUM(G5:G8,0) -> 79863 | H9: =SUM(H5:H8,0) -> 79738 | K9: =SUM(K5:K8,0) -> 8234.13 | L9: =SUM(L5:L8,0) -> 8978.74 | M9: =SUM(M5:M8,0) -> 8978.74 | N9: =SUM(N5:N8,0) -> 10523.06 | O9: =SUM(O5:O8,0) -> 12323.89 | P9: =SUM(P5:P8,0) -> 13357.17
B11: Fixed Assets Net Block | C11: =IFERROR('Data Sheet1'!F62,0) -> 51443 | D11: =IFERROR('Data Sheet1'!G62,0) -> 51473 | E11: =IFERROR('Data Sheet1'!H62,0) -> 52678 | F11: =IFERROR('Data Sheet1'!I62,0) -> 53744 | G11: =IFERROR('Data Sheet1'!J62,0) -> 54335 | H11: =IFERROR('Data Sheet1'!K62,0) -> 57428 | K11: =IFERROR('Data Sheet2'!F62,0) -> 2994.67 | L11: =IFERROR('Data Sheet2'!G62,0) -> 3043.7 | M11: =IFERROR('Data Sheet2'!H62,0) -> 3043.7 | N11: =IFERROR('Data Sheet2'!I62,0) -> 3460.25 | O11: =IFERROR('Data Sheet2'!J62,0) -> 5473.61 | P11: =IFERROR('Data Sheet2'!K62,0) -> 6290.42
B12: Capital Work in Progress | C12: =IFERROR('Data Sheet1'!F63,0) -> 745 | D12: =IFERROR('Data Sheet1'!G63,0) -> 1313 | E12: =IFERROR('Data Sheet1'!H63,0) -> 1132 | F12: =IFERROR('Data Sheet1'!I63,0) -> 1025 | G12: =IFERROR('Data Sheet1'!J63,0) -> 1009 | H12: =IFERROR('Data Sheet1'!K63,0) -> 880 | K12: =IFERROR('Data Sheet2'!F63,0) -> 246.23 | L12: =IFERROR('Data Sheet2'!G63,0) -> 358.36 | M12: =IFERROR('Data Sheet2'!H63,0) -> 358.36 | N12: =IFERROR('Data Sheet2'!I63,0) -> 1741.71 | O12: =IFERROR('Data Sheet2'!J63,0) -> 1172.56 | P12: =IFERROR('Data Sheet2'!K63,0) -> 506.98
B13: Investments | C13: =IFERROR('Data Sheet1'!F64,0) -> 2709 | D13: =IFERROR('Data Sheet1'!G64,0) -> 3521 | E13: =IFERROR('Data Sheet1'!H64,0) -> 2882 | F13: =IFERROR('Data Sheet1'!I64,0) -> 4625 | G13: =IFERROR('Data Sheet1'!J64,0) -> 3810 | H13: =IFERROR('Data Sheet1'!K64,0) -> 4359 | K13: =IFERROR('Data Sheet2'!F64,0) -> 773.98 | L13: =IFERROR('Data Sheet2'!G64,0) -> 777.54 | M13: =IFERROR('Data Sheet2'!H64,0) -> 777.54 | N13: =IFERROR('Data Sheet2'!I64,0) -> 463.87 | O13: =IFERROR('Data Sheet2'!J64,0) -> 705.6 | P13: =IFERROR('Data Sheet2'!K64,0) -> 705.6
B14: Other Assets | C14: =IFERROR('Data Sheet1'!F65-SUM('Data Sheet1'!F67:F69),0) -> 4035 | D14: =IFERROR('Data Sheet1'!G65-SUM('Data Sheet1'!G67:G69),0) -> 4021 | E14: =IFERROR('Data Sheet1'!H65-SUM('Data Sheet1'!H67:H69),0) -> 4377 | F14: =IFERROR('Data Sheet1'!I65-SUM('Data Sheet1'!I67:I69),0) -> 4517 | G14: =IFERROR('Data Sheet1'!J65-SUM('Data Sheet1'!J67:J69),0) -> 4921 | H14: =IFERROR('Data Sheet1'!K65-SUM('Data Sheet1'!K67:K69),0) -> 5655 | K14: =IFERROR('Data Sheet2'!F65-SUM('Data Sheet2'!F67:F69),0) -> 1725.22 | L14: =IFERROR('Data Sheet2'!G65-SUM('Data Sheet2'!G67:G69),0) -> 1732.93 | M14: =IFERROR('Data Sheet2'!H65-SUM('Data Sheet2'!H67:H69),0) -> 1732.93 | N14: =IFERROR('Data Sheet2'!I65-SUM('Data Sheet2'!I67:I69),0) -> 1688.56 | O14: =IFERROR('Data Sheet2'!J65-SUM('Data Sheet2'!J67:J69),0) -> 1663.18 | P14: =IFERROR('Data Sheet2'!K65-SUM('Data Sheet2'!K67:K69),0) -> 1614.61
B15: Total Non Current Assets | C15: =SUM(C11:C14) -> 58932 | D15: =SUM(D11:D14) -> 60328 | E15: =SUM(E11:E14) -> 61069 | F15: =SUM(F11:F14) -> 63911 | G15: =SUM(G11:G14) -> 64075 | H15: =SUM(H11:H14) -> 68322 | K15: =SUM(K11:K14) -> 5740.1 | L15: =SUM(L11:L14) -> 5912.53 | M15: =SUM(M11:M14) -> 5912.53 | N15: =SUM(N11:N14) -> 7354.39 | O15: =SUM(O11:O14) -> 9014.95 | P15: =SUM(P11:P14) -> 9117.61
B17: Receivables | C17: =IFERROR('Data Sheet1'!F67,0) -> 1758 | D17: =IFERROR('Data Sheet1'!G67,0) -> 2236 | E17: =IFERROR('Data Sheet1'!H67,0) -> 3079 | F17: =IFERROR('Data Sheet1'!I67,0) -> 2997 | G17: =IFERROR('Data Sheet1'!J67,0) -> 3819 | H17: =IFERROR('Data Sheet1'!K67,0) -> 3379 | K17: =IFERROR('Data Sheet2'!F67,0) -> 165.97 | L17: =IFERROR('Data Sheet2'!G67,0) -> 191.89 | M17: =IFERROR('Data Sheet2'!H67,0) -> 191.89 | N17: =IFERROR('Data Sheet2'!I67,0) -> 300.46 | O17: =IFERROR('Data Sheet2'!J67,0) -> 363.15 | P17: =IFERROR('Data Sheet2'!K67,0) -> 329.47
B18: Inventory | C18: =IFERROR('Data Sheet1'!F68,0) -> 3579 | D18: =IFERROR('Data Sheet1'!G68,0) -> 4096 | E18: =IFERROR('Data Sheet1'!H68,0) -> 4251 | F18: =IFERROR('Data Sheet1'!I68,0) -> 4022 | G18: =IFERROR('Data Sheet1'!J68,0) -> 4415 | H18: =IFERROR('Data Sheet1'!K68,0) -> 4789 | K18: =IFERROR('Data Sheet2'!F68,0) -> 1592.65 | L18: =IFERROR('Data Sheet2'!G68,0) -> 1928.77 | M18: =IFERROR('Data Sheet2'!H68,0) -> 1928.77 | N18: =IFERROR('Data Sheet2'!I68,0) -> 2089.36 | O18: =IFERROR('Data Sheet2'!J68,0) -> 2850.14 | P18: =IFERROR('Data Sheet2'!K68,0) -> 2569.22
B19: Cash & Bank | C19: =IFERROR('Data Sheet1'!F69,0) -> 4471 | D19: =IFERROR('Data Sheet1'!G69,0) -> 3846 | E19: =IFERROR('Data Sheet1'!H69,0) -> 4678 | F19: =IFERROR('Data Sheet1'!I69,0) -> 7559 | G19: =IFERROR('Data Sheet1'!J69,0) -> 7554 | H19: =IFERROR('Data Sheet1'!K69,0) -> 3248 | K19: =IFERROR('Data Sheet2'!F69,0) -> 735.41 | L19: =IFERROR('Data Sheet2'!G69,0) -> 945.55 | M19: =IFERROR('Data Sheet2'!H69,0) -> 945.55 | N19: =IFERROR('Data Sheet2'!I69,0) -> 778.85 | O19: =IFERROR('Data Sheet2'!J69,0) -> 95.65 | P19: =IFERROR('Data Sheet2'!K69,0) -> 1340.87
B20: Total Current Assets | C20: =IFERROR(SUM(C17:C19),0) -> 9808 | D20: =IFERROR(SUM(D17:D19),0) -> 10178 | E20: =IFERROR(SUM(E17:E19),0) -> 12008 | F20: =IFERROR(SUM(F17:F19),0) -> 14578 | G20: =IFERROR(SUM(G17:G19),0) -> 15788 | H20: =IFERROR(SUM(H17:H19),0) -> 11416 | K20: =IFERROR(SUM(K17:K19),0) -> 2494.03 | L20: =IFERROR(SUM(L17:L19),0) -> 3066.21 | M20: =IFERROR(SUM(M17:M19),0) -> 3066.21 | N20: =IFERROR(SUM(N17:N19),0) -> 3168.67 | O20: =IFERROR(SUM(O17:O19),0) -> 3308.94 | P20: =IFERROR(SUM(P17:P19),0) -> 4239.56
B22: Total Assets | C22: =IFERROR(C20+C15,0) -> 68740 | D22: =IFERROR(D20+D15,0) -> 70506 | E22: =IFERROR(E20+E15,0) -> 73077 | F22: =IFERROR(F20+F15,0) -> 78489 | G22: =IFERROR(G20+G15,0) -> 79863 | H22: =IFERROR(H20+H15,0) -> 79738 | I22: =IFERROR(I20+I15,0) -> 0 | K22: =IFERROR(K20+K15,0) -> 8234.13 | L22: =IFERROR(L20+L15,0) -> 8978.74 | M22: =IFERROR(M20+M15,0) -> 8978.74 | N22: =IFERROR(N20+N15,0) -> 10523.06 | O22: =IFERROR(O20+O15,0) -> 12323.89 | P22: =IFERROR(P20+P15,0) -> 13357.17
B24: Check | C24: =C22=C9 -> TRUE | D24: =D22=D9 -> TRUE | E24: =E22=E9 -> TRUE | F24: =F22=F9 -> TRUE | G24: =G22=G9 -> TRUE | H24: =H22=H9 -> TRUE | K24: =K22=K9 -> TRUE | L24: =L22=L9 -> TRUE | M24: =M22=M9 -> TRUE | N24: =N22=N9 -> TRUE | O24: =O22=O9 -> TRUE | P24: =P22=P9 -> TRUE

Sheet Cash Flow Statement 
A2: # | D2: =" Cash Flow Statement - "&'Data Sheet1'!B1 -> Cash Flow Statement - HINDUSTAN UNILEVER LTD | L2: =" Cash Flow Statement - "&'Data Sheet2'!B1 -> Cash Flow Statement - NESTLE INDIA LTD
B3: Years | C3: ='Data Sheet1'!F16 -> 44286 | D3: ='Data Sheet1'!G16 -> 44651 | E3: ='Data Sheet1'!H16 -> 45016 | F3: ='Data Sheet1'!I16 -> 45382 | G3: ='Data Sheet1'!J16 -> 45747 | H3: ='Data Sheet1'!K16 -> 46112 | K3: =C3 -> 44286 | L3: =D3 -> 44651 | M3: =E3 -> 45016 | N3: =F3 -> 45382 | O3: =G3 -> 45747 | P3: =H3 -> 46112 | Q3: LTM
B5: Operating Activites
B6: Profit from operations | C6: =IFERROR('Cashflow H'!C5,0) -> 9723 | D6: =IFERROR('Cashflow H'!D5,0) -> 11672 | E6: =IFERROR('Cashflow H'!E5,0) -> 12829 | F6: =IFERROR('Cashflow H'!F5,0) -> 14089 | G6: =IFERROR('Cashflow H'!G5,0) -> 14537 | H6: =IFERROR('Cashflow H'!H5,0) -> 14942 | K6: =IFERROR('Cash flow N'!C5,0) -> 3136 | L6: =IFERROR('Cash flow N'!D5,0) -> 3609 | M6: =IFERROR('Cash flow N'!E5,0) -> 4388 | N6: =IFERROR('Cash flow N'!F5,0) -> 5722 | O6: =IFERROR('Cash flow N'!G5,0) -> 4672 | P6: =IFERROR('Cash flow N'!H5,0) -> 5326
B7: Receivables | C7: =IFERROR('Cashflow H'!C6,0) -> 0 | D7: =IFERROR('Cashflow H'!D6,0) -> 0 | E7: =IFERROR('Cashflow H'!E6,0) -> 0 | F7: =IFERROR('Cashflow H'!F6,0) -> 0 | G7: =IFERROR('Cashflow H'!G6,0) -> 0 | H7: =IFERROR('Cashflow H'!H6,0) -> 0 | K7: =IFERROR('Cash flow N'!C6,0) -> -2 | L7: =IFERROR('Cash flow N'!D6,0) -> -28 | M7: =IFERROR('Cash flow N'!E6,0) -> -11 | N7: =IFERROR('Cash flow N'!F6,0) -> -109 | O7: =IFERROR('Cash flow N'!G6,0) -> -70 | P7: =IFERROR('Cash flow N'!H6,0) -> 34
B8: Inventory | C8: =IFERROR('Cashflow H'!C7,0) -> -331 | D8: =IFERROR('Cashflow H'!D7,0) -> -543 | E8: =IFERROR('Cashflow H'!E7,0) -> -758 | F8: =IFERROR('Cashflow H'!F7,0) -> -339 | G8: =IFERROR('Cashflow H'!G7,0) -> 74 | H8: =IFERROR('Cashflow H'!H7,0) -> -584 | K8: =IFERROR('Cash flow N'!C7,0) -> -169 | L8: =IFERROR('Cash flow N'!D7,0) -> -336 | M8: =IFERROR('Cash flow N'!E7,0) -> 56 | N8: =IFERROR('Cash flow N'!F7,0) -> -161 | O8: =IFERROR('Cash flow N'!G7,0) -> -767 | P8: =IFERROR('Cash flow N'!H7,0) -> 281
B9: Payables | C9: =IFERROR('Cashflow H'!C8,0) -> 0 | D9: =IFERROR('Cashflow H'!D8,0) -> 0 | E9: =IFERROR('Cashflow H'!E8,0) -> 0 | F9: =IFERROR('Cashflow H'!F8,0) -> 0 | G9: =IFERROR('Cashflow H'!G8,0) -> 0 | H9: =IFERROR('Cashflow H'!H8,0) -> 0 | K9: =IFERROR('Cash flow N'!C8,0) -> 217 | L9: =IFERROR('Cash flow N'!D8,0) -> 178 | M9: =IFERROR('Cash flow N'!E8,0) -> 68 | N9: =IFERROR('Cash flow N'!F8,0) -> 310 | O9: =IFERROR('Cash flow N'!G8,0) -> 134 | P9: =IFERROR('Cash flow N'!H8,0) -> 588
B10: Loans Advances | C10: =IFERROR('Cashflow H'!C9,0) -> 0 | D10: =IFERROR('Cashflow H'!D9,0) -> 0 | E10: =IFERROR('Cashflow H'!E9,0) -> 0 | F10: =IFERROR('Cashflow H'!F9,0) -> 0 | G10: =IFERROR('Cashflow H'!G9,0) -> 0 | H10: =IFERROR('Cashflow H'!H9,0) -> 0 | K10: =IFERROR('Cash flow N'!C9,0) -> -40 | L10: =IFERROR('Cash flow N'!D9,0) -> -30 | M10: =IFERROR('Cash flow N'!E9,0) -> -30 | N10: =IFERROR('Cash flow N'!F9,0) -> -21 | O10: =IFERROR('Cash flow N'!G9,0) -> -199 | P10: =IFERROR('Cash flow N'!H9,0) -> -73
B11: Other WC items | C11: =IFERROR('Cashflow H'!C10,0) -> 742 | D11: =IFERROR('Cashflow H'!D10,0) -> 442 | E11: =IFERROR('Cashflow H'!E10,0) -> -242 | F11: =IFERROR('Cashflow H'!F10,0) -> -621 | G11: =IFERROR('Cashflow H'!G10,0) -> 1239 | H11: =IFERROR('Cashflow H'!H10,0) -> -204 | K11: =IFERROR('Cash flow N'!C11,0) -> -179 | L11: =IFERROR('Cash flow N'!D11,0) -> 185 | M11: =IFERROR('Cash flow N'!E11,0) -> -19 | N11: =IFERROR('Cash flow N'!F11,0) -> -268 | O11: =IFERROR('Cash flow N'!G11,0) -> 155 | P11: =IFERROR('Cash flow N'!H11,0) -> -37
B12: Working capital changes | C12: =IFERROR('Cashflow H'!C11,0) -> 411 | D12: =IFERROR('Cashflow H'!D11,0) -> -101 | E12: =IFERROR('Cashflow H'!E11,0) -> -1000 | F12: =IFERROR('Cashflow H'!F11,0) -> -960 | G12: =IFERROR('Cashflow H'!G11,0) -> 1313 | H12: =IFERROR('Cashflow H'!H11,0) -> -788 | K12: =IFERROR('Cash flow N'!C12,0) -> -172 | L12: =IFERROR('Cash flow N'!D12,0) -> -30 | M12: =IFERROR('Cash flow N'!E12,0) -> 63 | N12: =IFERROR('Cash flow N'!F12,0) -> -249 | O12: =IFERROR('Cash flow N'!G12,0) -> -747 | P12: =IFERROR('Cash flow N'!H12,0) -> 793
B13: Direct taxes | C13: =IFERROR('Cashflow H'!C12,0) -> -2505 | D13: =IFERROR('Cashflow H'!D12,0) -> -2407 | E13: =IFERROR('Cashflow H'!E12,0) -> -2784 | F13: =IFERROR('Cashflow H'!F12,0) -> -3138 | G13: =IFERROR('Cashflow H'!G12,0) -> -381 | H13: =IFERROR('Cashflow H'!H12,0) -> -2268 | K13: =IFERROR('Cash flow N'!C13,0) -> -729 | L13: =IFERROR('Cash flow N'!D13,0) -> -841 | M13: =IFERROR('Cash flow N'!E13,0) -> -1059 | N13: =IFERROR('Cash flow N'!F13,0) -> -1299 | O13: =IFERROR('Cash flow N'!G13,0) -> -990 | P13: =IFERROR('Cash flow N'!H13,0) -> -1071
B14: Cash from Operating Activity | C14: =SUM(C6:C13) -> 8040 | D14: =SUM(D6:D13) -> 9063 | E14: =SUM(E6:E13) -> 8045 | F14: =SUM(F6:F13) -> 9031 | G14: =SUM(G6:G13) -> 16782 | H14: =SUM(H6:H13) -> 11098 | K14: =SUM(K6:K13) -> 2062 | L14: =SUM(L6:L13) -> 2707 | M14: =SUM(M6:M13) -> 3456 | N14: =SUM(N6:N13) -> 3925 | O14: =SUM(O6:O13) -> 2188 | P14: =SUM(P6:P13) -> 5841
B16: Investing Activity
B17: Fixed assets purchased | C17: =IFERROR('Cashflow H'!C16,0) -> -862 | D17: =IFERROR('Cashflow H'!D16,0) -> -4163 | E17: =IFERROR('Cashflow H'!E16,0) -> -1228 | F17: =IFERROR('Cashflow H'!F16,0) -> -1192 | G17: =IFERROR('Cashflow H'!G16,0) -> -1477 | H17: =IFERROR('Cashflow H'!H16,0) -> -1275 | K17: =IFERROR('Cash flow N'!C15,0) -> -735 | L17: =IFERROR('Cash flow N'!D15,0) -> -550 | M17: =IFERROR('Cash flow N'!E15,0) -> -1371 | N17: =IFERROR('Cash flow N'!F15,0) -> -1883 | O17: =IFERROR('Cash flow N'!G15,0) -> -2009 | P17: =IFERROR('Cash flow N'!H15,0) -> -830
B18: Fixed assets sold | C18: =IFERROR('Cashflow H'!C17,0) -> 52 | D18: =IFERROR('Cashflow H'!D17,0) -> 97 | E18: =IFERROR('Cashflow H'!E17,0) -> 175 | F18: =IFERROR('Cashflow H'!F17,0) -> 181 | G18: =IFERROR('Cashflow H'!G17,0) -> 20 | H18: =IFERROR('Cashflow H'!H17,0) -> 13 | K18: =IFERROR('Cash flow N'!C16,0) -> 4 | L18: =IFERROR('Cash flow N'!D16,0) -> 9 | M18: =IFERROR('Cash flow N'!E16,0) -> 7 | N18: =IFERROR('Cash flow N'!F16,0) -> 4 | O18: =IFERROR('Cash flow N'!G16,0) -> 4 | P18: =IFERROR('Cash flow N'!H16,0) -> 3
B19: Investments purchased | C19: =IFERROR('Cashflow H'!C18,0) -> -36090 | D19: =IFERROR('Cashflow H'!D18,0) -> -39920 | E19: =IFERROR('Cashflow H'!E18,0) -> -48522 | F19: =IFERROR('Cashflow H'!F18,0) -> -22649 | G19: =IFERROR('Cashflow H'!G18,0) -> -21337 | H19: =IFERROR('Cashflow H'!H18,0) -> -22957 | K19: =IFERROR('Cash flow N'!C17,0) -> 0 | L19: =IFERROR('Cash flow N'!D17,0) -> 0 | M19: =IFERROR('Cash flow N'!E17,0) -> 0 | N19: =IFERROR('Cash flow N'!F17,0) -> 0 | O19: =IFERROR('Cash flow N'!G17,0) -> 0 | P19: =IFERROR('Cash flow N'!H17,0) -> 0
B20: Investments sold | C20: =IFERROR('Cashflow H'!C19,0) -> 37690 | D20: =IFERROR('Cashflow H'!D19,0) -> 38486 | E20: =IFERROR('Cashflow H'!E19,0) -> 47786 | F20: =IFERROR('Cashflow H'!F19,0) -> 23462 | G20: =IFERROR('Cashflow H'!G19,0) -> 19846 | H20: =IFERROR('Cashflow H'!H19,0) -> 23987 | K20: =IFERROR('Cash flow N'!C18,0) -> 0 | L20: =IFERROR('Cash flow N'!D18,0) -> 25 | M20: =IFERROR('Cash flow N'!E18,0) -> 312 | N20: =IFERROR('Cash flow N'!F18,0) -> 284 | O20: =IFERROR('Cash flow N'!G18,0) -> 424 | P20: =IFERROR('Cash flow N'!H18,0) -> 0
B21: Interest received | C21: =IFERROR('Cashflow H'!C20,0) -> 351 | D21: =IFERROR('Cashflow H'!D20,0) -> 277 | E21: =IFERROR('Cashflow H'!E20,0) -> 161 | F21: =IFERROR('Cashflow H'!F20,0) -> 259 | G21: =IFERROR('Cashflow H'!G20,0) -> 425 | H21: =IFERROR('Cashflow H'!H20,0) -> 835 | K21: =IFERROR('Cash flow N'!C19,0) -> 125 | L21: =IFERROR('Cash flow N'!D19,0) -> 103 | M21: =IFERROR('Cash flow N'!E19,0) -> 0 | N21: =IFERROR('Cash flow N'!F19,0) -> 167 | O21: =IFERROR('Cash flow N'!G19,0) -> 76 | P21: =IFERROR('Cash flow N'!H19,0) -> 34
B22: Dividends received | C22: =IFERROR('Cashflow H'!C21,0) -> 1 | D22: =IFERROR('Cashflow H'!D21,0) -> 1 | E22: =IFERROR('Cashflow H'!E21,0) -> 1 | F22: =IFERROR('Cashflow H'!F21,0) -> 2 | G22: =IFERROR('Cashflow H'!G21,0) -> 3 | H22: =IFERROR('Cashflow H'!H21,0) -> 0 | K22: =IFERROR('Cash flow N'!C20,0) -> 0 | L22: =IFERROR('Cash flow N'!D20,0) -> 0 | M22: =IFERROR('Cash flow N'!E20,0) -> 0 | N22: =IFERROR('Cash flow N'!F20,0) -> 0 | O22: =IFERROR('Cash flow N'!G20,0) -> 0 | P22: =IFERROR('Cash flow N'!H20,0) -> 0
B23: Acquisition of companies | C23: =IFERROR('Cashflow H'!C22,0) -> 0 | D23: =IFERROR('Cashflow H'!D22,0) -> 0 | E23: =IFERROR('Cashflow H'!E22,0) -> 0 | F23: =IFERROR('Cashflow H'!F22,0) -> -334 | G23: =IFERROR('Cashflow H'!G22,0) -> 0 | H23: =IFERROR('Cashflow H'!H22,0) -> 0 | K23: =IFERROR('Cash flow N'!C21,0) -> 0 | L23: =IFERROR('Cash flow N'!D21,0) -> 0 | M23: =IFERROR('Cash flow N'!E21,0) -> 0 | N23: =IFERROR('Cash flow N'!F21,0) -> 0 | O23: =IFERROR('Cash flow N'!G21,0) -> -706 | P23: =IFERROR('Cash flow N'!H21,0) -> 0
B24: Other investing items | C24: =IFERROR('Cashflow H'!C23,0) -> 649 | D24: =IFERROR('Cashflow H'!D23,0) -> 3994 | E24: =IFERROR('Cashflow H'!E23,0) -> -101 | F24: =IFERROR('Cashflow H'!F23,0) -> -1213 | G24: =IFERROR('Cashflow H'!G23,0) -> -2804 | H24: =IFERROR('Cashflow H'!H23,0) -> 5870 | K24: =IFERROR('Cash flow N'!C22,0) -> -1314 | L24: =IFERROR('Cash flow N'!D22,0) -> 20 | M24: =IFERROR('Cash flow N'!E22,0) -> 126 | N24: =IFERROR('Cash flow N'!F22,0) -> 190 | O24: =IFERROR('Cash flow N'!G22,0) -> 400 | P24: =IFERROR('Cash flow N'!H22,0) -> 168
B25: Cash from Inveting Activity | C25: =SUM(C17:C24) -> 1791 | D25: =SUM(D17:D24) -> -1228 | E25: =SUM(E17:E24) -> -1728 | F25: =SUM(F17:F24) -> -1484 | G25: =SUM(G17:G24) -> -5324 | H25: =SUM(H17:H24) -> 6473 | K25: =SUM(K17:K24) -> -1920 | L25: =SUM(L17:L24) -> -393 | M25: =SUM(M17:M24) -> -926 | N25: =SUM(N17:N24) -> -1238 | O25: =SUM(O17:O24) -> -1811 | P25: =SUM(P17:P24) -> -625
B27: Financial Activity
B28: Proceeds from shares | C28: =IFERROR('Cashflow H'!C25,0) -> 0 | D28: =IFERROR('Cashflow H'!D25,0) -> 0 | E28: =IFERROR('Cashflow H'!E25,0) -> 0 | F28: =IFERROR('Cashflow H'!F25,0) -> 0 | G28: =IFERROR('Cashflow H'!G25,0) -> 0 | H28: =IFERROR('Cashflow H'!H25,0) -> 0 | K28: =IFERROR('Cash flow N'!C24,0) -> 24 | L28: =IFERROR('Cash flow N'!D24,0) -> 0 | M28: =IFERROR('Cash flow N'!E24,0) -> 0 | N28: =IFERROR('Cash flow N'!F24,0) -> 0 | O28: =IFERROR('Cash flow N'!G24,0) -> 726 | P28: =IFERROR('Cash flow N'!H24,0) -> 0
B29: Repayment of borrowings | C29: =IFERROR('Cashflow H'!C26,0) -> 0 | D29: =IFERROR('Cashflow H'!D26,0) -> 188 | E29: =IFERROR('Cashflow H'!E26,0) -> 55 | F29: =IFERROR('Cashflow H'!F26,0) -> 286 | G29: =IFERROR('Cashflow H'!G26,0) -> 0 | H29: =IFERROR('Cashflow H'!H26,0) -> 0 | K29: =IFERROR('Cash flow N'!C25,0) -> -24 | L29: =IFERROR('Cash flow N'!D25,0) -> 0 | M29: =IFERROR('Cash flow N'!E25,0) -> 0 | N29: =IFERROR('Cash flow N'!F25,0) -> 0 | O29: =IFERROR('Cash flow N'!G25,0) -> 0 | P29: =IFERROR('Cash flow N'!H25,0) -> -726
B30: Investment subsidy | C30: =IFERROR('Cashflow H'!C27,0) -> -99 | D30: =IFERROR('Cashflow H'!D27,0) -> -188 | E30: =IFERROR('Cashflow H'!E27,0) -> -55 | F30: =IFERROR('Cashflow H'!F27,0) -> -208 | G30: =IFERROR('Cashflow H'!G27,0) -> -85 | H30: =IFERROR('Cashflow H'!H27,0) -> 0 | K30: =IFERROR('Cash flow N'!C26,0) -> 0 | L30: =IFERROR('Cash flow N'!D26,0) -> 0 | M30: =IFERROR('Cash flow N'!E26,0) -> 0 | N30: =IFERROR('Cash flow N'!F26,0) -> 0 | O30: =IFERROR('Cash flow N'!G26,0) -> 0 | P30: =IFERROR('Cash flow N'!H26,0) -> 0
B31: Interest paid fin | C31: =IFERROR('Cashflow H'!C28,0) -> -90 | D31: =IFERROR('Cashflow H'!D28,0) -> -92 | E31: =IFERROR('Cashflow H'!E28,0) -> -82 | F31: =IFERROR('Cashflow H'!F28,0) -> -88 | G31: =IFERROR('Cashflow H'!G28,0) -> -110 | H31: =IFERROR('Cashflow H'!H28,0) -> -130 | K31: =IFERROR('Cash flow N'!C27,0) -> -9 | L31: =IFERROR('Cash flow N'!D27,0) -> -18 | M31: =IFERROR('Cash flow N'!E27,0) -> -20 | N31: =IFERROR('Cash flow N'!F27,0) -> -26 | O31: =IFERROR('Cash flow N'!G27,0) -> -34 | P31: =IFERROR('Cash flow N'!H27,0) -> -50
B32: Dividends paid | C32: =IFERROR('Cashflow H'!C29,0) -> -5196 | D32: =IFERROR('Cashflow H'!D29,0) -> -8811 | E32: =IFERROR('Cashflow H'!E29,0) -> -7526 | F32: =IFERROR('Cashflow H'!F29,0) -> -8474 | G32: =IFERROR('Cashflow H'!G29,0) -> -9416 | H32: =IFERROR('Cashflow H'!H29,0) -> -12473 | K32: =IFERROR('Cash flow N'!C28,0) -> -1928 | L32: =IFERROR('Cash flow N'!D28,0) -> -2025 | M32: =IFERROR('Cash flow N'!E28,0) -> -2333 | N32: =IFERROR('Cash flow N'!F28,0) -> -3008 | O32: =IFERROR('Cash flow N'!G28,0) -> -2459 | P32: =IFERROR('Cash flow N'!H28,0) -> -2314
B33: Financial liabilities | C33: =IFERROR('Cashflow H'!C30,0) -> -373 | D33: =IFERROR('Cashflow H'!D30,0) -> -406 | E33: =IFERROR('Cashflow H'!E30,0) -> -407 | F33: =IFERROR('Cashflow H'!F30,0) -> -467 | G33: =IFERROR('Cashflow H'!G30,0) -> -423 | H33: =IFERROR('Cashflow H'!H30,0) -> -498 | K33: =IFERROR('Cash flow N'!C29,0) -> -79 | L33: =IFERROR('Cash flow N'!D29,0) -> -73 | M33: =IFERROR('Cash flow N'!E29,0) -> -166 | N33: =IFERROR('Cash flow N'!F29,0) -> -100 | O33: =IFERROR('Cash flow N'!G29,0) -> -76 | P33: =IFERROR('Cash flow N'!H29,0) -> -86
B34: Other financing items | C34: =IFERROR('Cashflow H'!C31,0) -> -1061 | D34: =IFERROR('Cashflow H'!D31,0) -> 0 | E34: =IFERROR('Cashflow H'!E31,0) -> 0 | F34: =IFERROR('Cashflow H'!F31,0) -> -2 | G34: =IFERROR('Cashflow H'!G31,0) -> 0 | H34: =IFERROR('Cashflow H'!H31,0) -> 0 | K34: =IFERROR('Cash flow N'!C30,0) -> -3 | L34: =IFERROR('Cash flow N'!D30,0) -> -7 | M34: =IFERROR('Cash flow N'!E30,0) -> 83 | N34: =IFERROR('Cash flow N'!F30,0) -> -1 | O34: =IFERROR('Cash flow N'!G30,0) -> -4 | P34: =IFERROR('Cash flow N'!H30,0) -> -3
B35: Cash From Financial Activity | C35: =SUM(C27:C34) -> -6819 | D35: =SUM(D27:D34) -> -9309 | E35: =SUM(E27:E34) -> -8015 | F35: =SUM(F27:F34) -> -8953 | G35: =SUM(G27:G34) -> -10034 | H35: =SUM(H27:H34) -> -13101 | K35: =SUM(K27:K34) -> -2019 | L35: =SUM(L27:L34) -> -2123 | M35: =SUM(M27:M34) -> -2436 | N35: =SUM(N27:N34) -> -3135 | O35: =SUM(O27:O34) -> -1847 | P35: =SUM(P27:P34) -> -3179
B37: Net Cash flow | C37: =IFERROR(SUM(C35,C25,C14),0) -> 3012 | D37: =IFERROR(SUM(D35,D25,D14),0) -> -1474 | E37: =IFERROR(SUM(E35,E25,E14),0) -> -1698 | F37: =IFERROR(SUM(F35,F25,F14),0) -> -1406 | G37: =IFERROR(SUM(G35,G25,G14),0) -> 1424 | H37: =IFERROR(SUM(H35,H25,H14),0) -> 4470 | K37: =IFERROR(SUM(K35,K25,K14),0) -> -1877 | L37: =IFERROR(SUM(L35,L25,L14),0) -> 191 | M37: =IFERROR(SUM(M35,M25,M14),0) -> 94 | N37: =IFERROR(SUM(N35,N25,N14),0) -> -448 | O37: =IFERROR(SUM(O35,O25,O14),0) -> -1470 | P37: =IFERROR(SUM(P35,P25,P14),0) -> 2037

Sheet Ratio Analysis
B2: ="Ratio Analysis of - "&'Data Sheet1'!B1 -> Ratio Analysis of - HINDUSTAN UNILEVER LTD | L2: ="Ratio Analysis of - "&'Data Sheet2'!B1 -> Ratio Analysis of - NESTLE INDIA LTD
B3: Years | C3: ='Data Sheet1'!F16 -> 44286 | D3: ='Data Sheet1'!G16 -> 44651 | E3: ='Data Sheet1'!H16 -> 45016 | F3: ='Data Sheet1'!I16 -> 45382 | G3: ='Data Sheet1'!J16 -> 45747 | H3: ='Data Sheet1'!K16 -> 46112 | K3: =C3 -> 44286 | L3: =D3 -> 44651 | M3: =E3 -> 45016 | N3: =F3 -> 45382 | O3: =G3 -> 45747 | P3: =H3 -> 46112
B5: SalesGrowth | D5: ='Income Statement'!D8 -> 0.11520796 | E5: ='Income Statement'!E8 -> 0.15509286 | F5: ='Income Statement'!F8 -> 0.021723341 | G5: ='Income Statement'!G8 -> -0.0091766835 | H5: ='Income Statement'!H8 -> 0.051200104 | L5: ='Income Statement'!M8 -> 0.1462879 | M5: ='Income Statement'!N8 -> 0.13193734 | N5: ='Income Statement'!O8 -> 0.27541082 | O5: ='Income Statement'!P8 -> -0.17185984 | P5: ='Income Statement'!Q8 -> 0.14617881
B6: EBITDA Growth | D6: ='Income Statement'!D19/'Income Statement'!C19-1 -> 0.10588336 | E6: ='Income Statement'!E19/'Income Statement'!D19-1 -> 0.10033445 | F6: ='Income Statement'!F19/'Income Statement'!E19-1 -> 0.036191419 | G6: ='Income Statement'!G19/'Income Statement'!F19-1 -> 0.0026604816 | H6: ='Income Statement'!H19/'Income Statement'!G19-1 -> 0.023200435 | L6: ='Income Statement'!M19/'Income Statement'!L19-1 -> 0.040391309 | M6: ='Income Statement'!N19/'Income Statement'!M19-1 -> 0.20632492 | N6: ='Income Statement'!O19/'Income Statement'!N19-1 -> 0.30689624 | O6: ='Income Statement'!P19/'Income Statement'!O19-1 -> -0.18342769 | P6: ='Income Statement'!Q19/'Income Statement'!P19-1 -> 0.1122601
B7: EBIT Growth | D7: =IFERROR(('Income Statement'!D28+'Income Statement'!D22)/('Income Statement'!C28+'Income Statement'!C22)-1,0) -> 0.11504928 | E7: =IFERROR(('Income Statement'!E28+'Income Statement'!E22)/('Income Statement'!D28+'Income Statement'!D22)-1,0) -> 0.10572837 | F7: =IFERROR(('Income Statement'!F28+'Income Statement'!F22)/('Income Statement'!E28+'Income Statement'!E22)-1,0) -> 0.033282091 | G7: =IFERROR(('Income Statement'!G28+'Income Statement'!G22)/('Income Statement'!F28+'Income Statement'!F22)-1,0) -> 0.00014877631 | H7: =IFERROR(('Income Statement'!H28+'Income Statement'!H22)/('Income Statement'!G28+'Income Statement'!G22)-1,0) -> 0.019412421 | L7: =IFERROR(('Income Statement'!M28+'Income Statement'!M22)/('Income Statement'!L28+'Income Statement'!L22)-1,0) -> 0.041590727 | M7: =IFERROR(('Income Statement'!N28+'Income Statement'!N22)/('Income Statement'!M28+'Income Statement'!M22)-1,0) -> 0.22365649 | N7: =IFERROR(('Income Statement'!O28+'Income Statement'!O22)/('Income Statement'!N28+'Income Statement'!N22)-1,0) -> 0.30511271 | O7: =IFERROR(('Income Statement'!P28+'Income Statement'!P22)/('Income Statement'!O28+'Income Statement'!O22)-1,0) -> -0.19789323 | P7: =IFERROR(('Income Statement'!Q28+'Income Statement'!Q22)/('Income Statement'!P28+'Income Statement'!P22)-1,0) -> 0.088934894
B8: Net Profit Growth | D8: ='Income Statement'!D34/'Income Statement'!C34-1 -> 0.10780432 | E8: ='Income Statement'!E34/'Income Statement'!D34-1 -> 0.11783697 | F8: ='Income Statement'!F34/'Income Statement'!E34-1 -> -0.023723569 | G8: ='Income Statement'!G34/'Income Statement'!F34-1 -> -0.015742208 | H8: ='Income Statement'!H34/'Income Statement'!G34-1 -> 0.08802061 | L8: ='Income Statement'!M34/'Income Statement'!L34-1 -> 0.023520815 | M8: ='Income Statement'!N34/'Income Statement'!M34-1 -> 0.26274275 | N8: ='Income Statement'!O34/'Income Statement'!N34-1 -> 0.30892386 | O8: ='Income Statement'!P34/'Income Statement'!O34-1 -> -0.21500855 | P8: ='Income Statement'!Q34/'Income Statement'!P34-1 -> 0.14242651
B9: Dividend Growth | D9: ='Income Statement'!D42/'Income Statement'!C42-1 -> -0.16049383 | E9: ='Income Statement'!E42/'Income Statement'!D42-1 -> 0.14705882 | F9: ='Income Statement'!F42/'Income Statement'!E42-1 -> 0.076923077 | G9: ='Income Statement'!G42/'Income Statement'!F42-1 -> 0.26190476 | H9: ='Income Statement'!H42/'Income Statement'!G42-1 -> -0.22641509 | L9: ='Income Statement'!M42/'Income Statement'!L42-1 -> 0.1 | M9: ='Income Statement'!N42/'Income Statement'!M42-1 -> -0.20908997 | N9: ='Income Statement'!O42/'Income Statement'!N42-1 -> 0.85028222 | O9: ='Income Statement'!P42/'Income Statement'!O42-1 -> -0.1614896 | P9: ='Income Statement'!Q42/'Income Statement'!P42-1 -> -0.11115721
B11: Gross Margin | C11: ='Income Statement'!C14 -> 0.46200136 | D11: ='Income Statement'!D14 -> 0.44579186 | E11: ='Income Statement'!E14 -> 0.41596236 | F11: ='Income Statement'!F14 -> 0.45632997 | G11: ='Income Statement'!G14 -> 0.45344704 | H11: ='Income Statement'!H14 -> 0.44726066 | K11: ='Income Statement'!L14 -> 0.42192612 | L11: ='Income Statement'!M14 -> 0.39505686 | M11: ='Income Statement'!N14 -> 0.46242138 | N11: ='Income Statement'!O14 -> 0.4219159 | O11: ='Income Statement'!P14 -> 0.42119024 | P11: ='Income Statement'!Q14 -> 0.41144999
B12: EBITDA Margin | C12: ='Income Statement'!C20 -> 0.24721443 | D12: ='Income Statement'!D20 -> 0.24514739 | E12: ='Income Statement'!E20 -> 0.23352592 | F12: ='Income Statement'!F20 -> 0.23683275 | G12: ='Income Statement'!G20 -> 0.23966214 | H12: ='Income Statement'!H20 -> 0.23327853 | K12: ='Income Statement'!L20 -> 0.24167282 | L12: ='Income Statement'!M20 -> 0.21934656 | M12: ='Income Statement'!N20 -> 0.23376137 | N12: ='Income Statement'!O20 -> 0.23953211 | O12: ='Income Statement'!P20 -> 0.23618622 | P12: ='Income Statement'!Q20 -> 0.22919679
B13: EBT Margin | C13: ='Income Statement'!C29 -> 0.22188909 | D13: ='Income Statement'!D29 -> 0.22232391 | E13: ='Income Statement'!E29 -> 0.21287554 | F13: ='Income Statement'!F29 -> 0.21179075 | G13: ='Income Statement'!G29 -> 0.21301852 | H13: ='Income Statement'!H29 -> 0.20624186 | K13: ='Income Statement'!L29 -> 0.20146412 | L13: ='Income Statement'!M29 -> 0.18634772 | M13: ='Income Statement'!N29 -> 0.20509926 | N13: ='Income Statement'!O29 -> 0.21029364 | O13: ='Income Statement'!P29 -> 0.20272741 | P13: ='Income Statement'!Q29 -> 0.19216138
B14: Net Profit Margin | C14: ='Income Statement'!C35 -> 0.16647529 | D14: ='Income Statement'!D35 -> 0.16537009 | E14: ='Income Statement'!E35 -> 0.16003632 | F14: ='Income Statement'!F35 -> 0.1529178 | G14: ='Income Statement'!G35 -> 0.15190451 | H14: ='Income Statement'!H35 -> 0.15722529 | K14: ='Income Statement'!L35 -> 0.15133655 | L14: ='Income Statement'!M35 -> 0.13512845 | M14: ='Income Statement'!N35 -> 0.15074374 | N14: ='Income Statement'!O35 -> 0.15470472 | O14: ='Income Statement'!P35 -> 0.14664412 | P14: ='Income Statement'!Q35 -> 0.14616405
B16: SalesExpenses%Sales | C16: ='Income Statement'!C17 -> 0.21478694 | D16: ='Income Statement'!D17 -> 0.20064447 | E16: ='Income Statement'!E17 -> 0.18243645 | F16: ='Income Statement'!F17 -> 0.21949722 | G16: ='Income Statement'!G17 -> 0.21378489 | H16: ='Income Statement'!H17 -> 0.21398213 | K16: ='Income Statement'!L17 -> 0.1802533 | L16: ='Income Statement'!M17 -> 0.17571031 | M16: ='Income Statement'!N17 -> 0.22866001 | N16: ='Income Statement'!O17 -> 0.18238379 | O16: ='Income Statement'!P17 -> 0.18500403 | P16: ='Income Statement'!Q17 -> 0.1822532
B17: Depreciation%Sales | C17: ='Income Statement'!C26 -> 0.022837459 | D17: ='Income Statement'!D26 -> 0.020802349 | E17: ='Income Statement'!E26 -> 0.01876857 | F17: ='Income Statement'!F26 -> 0.019645858 | G17: ='Income Statement'!G26 -> 0.020431124 | H17: ='Income Statement'!H26 -> 0.020676925 | K17: ='Income Statement'!L26 -> 0.026526754 | L17: ='Income Statement'!M26 -> 0.023851036 | M17: ='Income Statement'!N26 -> 0.022425142 | N17: ='Income Statement'!O26 -> 0.023274271 | O17: ='Income Statement'!P26 -> 0.026726649 | P17: ='Income Statement'!Q26 -> 0.030198319
B18: OperatingIncome%Sales | C18: =C12 -> 0.24721443 | D18: =D12 -> 0.24514739 | E18: =E12 -> 0.23352592 | F18: =F12 -> 0.23683275 | G18: =G12 -> 0.23966214 | H18: =H12 -> 0.23327853 | K18: =K12 -> 0.24167282 | L18: =L12 -> 0.21934656 | M18: =M12 -> 0.23376137 | N18: =N12 -> 0.23953211 | O18: =O12 -> 0.23618622 | P18: =P12 -> 0.22919679
B20: Return on Capital Employed | C20: =IFERROR(('Income Statement'!C19-'Income Statement'!C25)/SUM('Balance Sheet'!C5:C7),0) -> 0.22133658 | D20: =IFERROR(('Income Statement'!D19-'Income Statement'!D25)/SUM('Balance Sheet'!D5:D7),0) -> 0.23483155 | E20: =IFERROR(('Income Statement'!E19-'Income Statement'!E25)/SUM('Balance Sheet'!E5:E7),0) -> 0.25250859 | F20: =IFERROR(('Income Statement'!F19-'Income Statement'!F25)/SUM('Balance Sheet'!F5:F7),0) -> 0.25507571 | G20: =IFERROR(('Income Statement'!G19-'Income Statement'!G25)/SUM('Balance Sheet'!G5:G7),0) -> 0.26336925 | H20: =IFERROR(('Income Statement'!H19-'Income Statement'!H25)/SUM('Balance Sheet'!H5:H7),0) -> 0.27293546 | K20: =IFERROR(('Income Statement'!L19-'Income Statement'!L25)/SUM('Balance Sheet'!K5:K7),0) -> 1.4331719 | L20: =IFERROR(('Income Statement'!M19-'Income Statement'!M25)/SUM('Balance Sheet'!L5:L7),0) -> 1.2101301 | M20: =IFERROR(('Income Statement'!N19-'Income Statement'!N25)/SUM('Balance Sheet'!M5:M7),0) -> 1.4807835 | N20: =IFERROR(('Income Statement'!O19-'Income Statement'!O25)/SUM('Balance Sheet'!N5:N7),0) -> 1.4314162 | O20: =IFERROR(('Income Statement'!P19-'Income Statement'!P25)/SUM('Balance Sheet'!O5:O7),0) -> 0.80079674 | P20: =IFERROR(('Income Statement'!Q19-'Income Statement'!Q25)/SUM('Balance Sheet'!P5:P7),0) -> 0.80087079
B21: Retained Earnings% | C21: ='Income Statement'!C45 -> 0 | D21: ='Income Statement'!D45 -> 0.078750144 | E21: ='Income Statement'!E45 -> 0.054667354 | F21: ='Income Statement'!F45 -> 0 | G21: ='Income Statement'!G45 -> 0 | H21: ='Income Statement'!H45 -> 0.049427782 | K21: ='Income Statement'!L45 -> 0.13555288 | L21: ='Income Statement'!M45 -> 0.070959943 | M21: ='Income Statement'!N45 -> 0.4181023 | N21: ='Income Statement'!O45 -> 0.17730699 | O21: ='Income Statement'!P45 -> 0.12121764 | P21: ='Income Statement'!Q45 -> 0.31628043
B22: Return on Equity% | C22: =IFERROR('Income Statement'!C34/SUM('Balance Sheet'!C5:C6),0) -> 0.16421949 | D22: =IFERROR('Income Statement'!D34/SUM('Balance Sheet'!D5:D6),0) -> 0.17677993 | E22: =IFERROR('Income Statement'!E34/SUM('Balance Sheet'!E5:E6),0) -> 0.19272821 | F22: =IFERROR('Income Statement'!F34/SUM('Balance Sheet'!F5:F6),0) -> 0.18479831 | G22: =IFERROR('Income Statement'!G34/SUM('Balance Sheet'!G5:G6),0) -> 0.18857536 | H22: =IFERROR('Income Statement'!H34/SUM('Balance Sheet'!H5:H6),0) -> 0.20796487 | K22: =IFERROR('Income Statement'!L34/SUM('Balance Sheet'!K5:K6),0) -> 1.1461225 | L22: =IFERROR('Income Statement'!M34/SUM('Balance Sheet'!L5:L6),0) -> 0.92846774 | M22: =IFERROR('Income Statement'!N34/SUM('Balance Sheet'!M5:M6),0) -> 1.1724159 | N22: =IFERROR('Income Statement'!O34/SUM('Balance Sheet'!N5:N6),0) -> 1.1295942 | O22: =IFERROR('Income Statement'!P34/SUM('Balance Sheet'!O5:O6),0) -> 0.71953657 | P22: =IFERROR('Income Statement'!Q34/SUM('Balance Sheet'!P5:P6),0) -> 0.63744905
B23: Self Sustained Growth Rate | C23: =C22*C21 -> 0 | D23: =D22*D21 -> 0.013921445 | E23: =E22*E21 -> 0.010535941 | F23: =F22*F21 -> 0 | G23: =G22*G21 -> 0 | H23: =H22*H21 -> 0.010279242 | K23: =K22*K21 -> 0.15536021 | L23: =L22*L21 -> 0.065884018 | M23: =M22*M21 -> 0.49018978 | N23: =N22*N21 -> 0.20028495 | O23: =O22*O21 -> 0.087220529 | P23: =P22*P21 -> 0.20161266
B24: Interest Coverage Ratio | C24: =('Income Statement'!C19-'Income Statement'!C25)/'Income Statement'!C22 -> 90.188034 | D24: =('Income Statement'!D19-'Income Statement'!D25)/'Income Statement'!D22 -> 111 | E24: =('Income Statement'!E19-'Income Statement'!E25)/'Income Statement'!E22 -> 114.12281 | F24: =('Income Statement'!F19-'Income Statement'!F25)/'Income Statement'!F22 -> 40.248503 | G24: =('Income Statement'!G19-'Income Statement'!G25)/'Income Statement'!G22 -> 35.288714 | H24: =('Income Statement'!H19-'Income Statement'!H25)/'Income Statement'!H22 -> 33.429268 | K24: =('Income Statement'!L19-'Income Statement'!L25)/'Income Statement'!L22 -> 15.724812 | L24: =('Income Statement'!M19-'Income Statement'!M25)/'Income Statement'!M22 -> 21.370771 | M24: =('Income Statement'!N19-'Income Statement'!N25)/'Income Statement'!N22 -> 33.884483 | N24: =('Income Statement'!O19-'Income Statement'!O25)/'Income Statement'!O22 -> 36.259331 | O24: =('Income Statement'!P19-'Income Statement'!P25)/'Income Statement'!P22 -> 31.113309 | P24: =('Income Statement'!Q19-'Income Statement'!Q25)/'Income Statement'!Q22 -> 29.105742
B26: Debtor Turnover Ratio | C26: ='Income Statement'!C7/'Balance Sheet'!C17 -> 26.750853 | D26: ='Income Statement'!D7/'Balance Sheet'!D17 -> 23.455277 | E26: ='Income Statement'!E7/'Balance Sheet'!E17 -> 19.675219 | F26: ='Income Statement'!F7/'Balance Sheet'!F17 -> 20.652653 | G26: ='Income Statement'!G7/'Balance Sheet'!G17 -> 16.058654 | H26: ='Income Statement'!H7/'Balance Sheet'!H17 -> 19.079017 | K26: ='Income Statement'!L7/'Balance Sheet'!K17 -> 88.814786 | L26: ='Income Statement'!M7/'Balance Sheet'!L17 -> 88.055448 | M26: ='Income Statement'!N7/'Balance Sheet'!M17 -> 99.67325 | N26: ='Income Statement'!O7/'Balance Sheet'!N17 -> 81.188478 | O26: ='Income Statement'!P7/'Balance Sheet'!O17 -> 55.628693 | P26: ='Income Statement'!Q7/'Balance Sheet'!P17 -> 70.278326
B27: Creditor Turnover Ratio | C27: ='Income Statement'!C7/'Balance Sheet'!C8 -> 2.2324124 | D27: ='Income Statement'!D7/'Balance Sheet'!D8 -> 2.5706303 | E27: ='Income Statement'!E7/'Balance Sheet'!E8 -> 2.8106152 | F27: ='Income Statement'!F7/'Balance Sheet'!F8 -> 2.4002792 | G27: ='Income Statement'!G7/'Balance Sheet'!G8 -> 2.1284837 | H27: ='Income Statement'!H7/'Balance Sheet'!H8 -> 2.1838014 | K27: ='Income Statement'!L7/'Balance Sheet'!K8 -> 2.4480784 | L27: ='Income Statement'!M7/'Balance Sheet'!L8 -> 2.7039246 | M27: ='Income Statement'!N7/'Balance Sheet'!M8 -> 3.0606732 | N27: ='Income Statement'!O7/'Balance Sheet'!N8 -> 3.5675891 | O27: ='Income Statement'!P7/'Balance Sheet'!O8 -> 2.8695846 | P27: ='Income Statement'!Q7/'Balance Sheet'!P8 -> 3.0451473
B28: Inventory Turnover | C28: ='Income Statement'!C7/'Balance Sheet'!C18 -> 13.139983 | D28: ='Income Statement'!D7/'Balance Sheet'!D18 -> 12.804199 | E28: ='Income Statement'!E7/'Balance Sheet'!E18 -> 14.250765 | F28: ='Income Statement'!F7/'Balance Sheet'!F18 -> 15.389359 | G28: ='Income Statement'!G7/'Balance Sheet'!G18 -> 13.890827 | H28: ='Income Statement'!H7/'Balance Sheet'!H18 -> 13.461683 | K28: ='Income Statement'!L7/'Balance Sheet'!K18 -> 9.2553857 | L28: ='Income Statement'!M7/'Balance Sheet'!L18 -> 8.7604847 | M28: ='Income Statement'!N7/'Balance Sheet'!M18 -> 9.9163197 | N28: ='Income Statement'!O7/'Balance Sheet'!N18 -> 11.675293 | O28: ='Income Statement'!P7/'Balance Sheet'!O18 -> 7.0879185 | P28: ='Income Statement'!Q7/'Balance Sheet'!P18 -> 9.0123072
B29: Fixed Asset Turnover | C29: ='Income Statement'!C7/'Balance Sheet'!C11 -> 0.91417686 | D29: ='Income Statement'!D7/'Balance Sheet'!D11 -> 1.0189031 | E29: ='Income Statement'!E7/'Balance Sheet'!E11 -> 1.1500057 | F29: ='Income Statement'!F7/'Balance Sheet'!F11 -> 1.151682 | G29: ='Income Statement'!G7/'Balance Sheet'!G11 -> 1.1287016 | H29: ='Income Statement'!H7/'Balance Sheet'!H11 -> 1.1225883 | K29: ='Income Statement'!L7/'Balance Sheet'!K11 -> 4.9222752 | L29: ='Income Statement'!M7/'Balance Sheet'!L11 -> 5.5514538 | M29: ='Income Statement'!N7/'Balance Sheet'!M11 -> 6.2838979 | N29: ='Income Statement'!O7/'Balance Sheet'!N11 -> 7.0497479 | O29: ='Income Statement'!P7/'Balance Sheet'!O11 -> 3.6907197 | P29: ='Income Statement'!Q7/'Balance Sheet'!P11 -> 3.6809307
B30: Capital Turnover Ratio | C30: ='Income Statement'!C7/SUM('Balance Sheet'!C5:C6) -> 0.98644964 | D30: ='Income Statement'!D7/SUM('Balance Sheet'!D5:D6) -> 1.0689957 | E30: ='Income Statement'!E7/SUM('Balance Sheet'!E5:E6) -> 1.204278 | F30: ='Income Statement'!F7/SUM('Balance Sheet'!F5:F6) -> 1.2084814 | G30: ='Income Statement'!G7/SUM('Balance Sheet'!G5:G6) -> 1.2414072 | H30: ='Income Statement'!H7/SUM('Balance Sheet'!H5:H6) -> 1.322719 | K30: ='Income Statement'!L7/SUM('Balance Sheet'!K5:K6) -> 7.5733361 | L30: ='Income Statement'!M7/SUM('Balance Sheet'!L5:L6) -> 6.8710012 | M30: ='Income Statement'!N7/SUM('Balance Sheet'!M5:M6) -> 7.7775428 | N30: ='Income Statement'!O7/SUM('Balance Sheet'!N5:N6) -> 7.3016142 | O30: ='Income Statement'!P7/SUM('Balance Sheet'!O5:O6) -> 4.9066854 | P30: ='Income Statement'!Q7/SUM('Balance Sheet'!P5:P6) -> 4.3611892

Sheet Graphical Represantation

Sheet Data>

Sheet Data Sheet1
A1: COMPANY NAME | B1: HINDUSTAN UNILEVER LTD | E1: =IF(B2<>B3, "A NEW VERSION OF THE WORKSHEET IS AVAILABLE", "")
A2: LATEST VERSION | B2: 2.1 | E2: PLEASE DO NOT MAKE ANY CHANGES TO THIS SHEET
A3: CURRENT VERSION | B3: 2.1
A5: META
A6: Number of shares | B6: =IF(B9>0, B9/B8, 0) -> 234.95913
A7: Face Value | B7: 1
A8: Current Price | B8: 2150.6
A9: Market Capitalization | B9: 505303.1
A15: PROFIT & LOSS | B15: =B26+B34 -> 7352 | K15: =K17-K18-K20-K21-K22-K23-K19 -> 17232
A16: Report Date | B16: 42825 | C16: 43190 | D16: 43555 | E16: 43921 | F16: 44286 | G16: 44651 | H16: 45016 | I16: 45382 | J16: 45747 | K16: 46112
A17: Sales | B17: 33162 | C17: 35545 | D17: 39310 | E17: 39783 | F17: 47028 | G17: 52446 | H17: 60580 | I17: 61896 | J17: 61328 | K17: 64468
A18: Raw Material Cost | B18: 13606 | C18: 14233 | D18: 15845 | E18: 15697 | F18: 20141 | G18: 22871 | H18: 28427 | I18: 26822 | J18: 26602 | K18: 29158
A19: Change in Inventory | B19: -144 | C19: 72 | D19: -12 | E19: 108 | F19: 405 | G19: 22 | H19: 75 | I19: 11 | J19: 125 | K19: 429
A20: Power and Fuel | B20: 295 | C20: 295 | D20: 308 | E20: 299 | F20: 339 | G20: 318 | H20: 384 | I20: 446 | J20: 403 | K20: 426
A21: Other Mfr. Exp | B21: 2887 | C21: 2998 | D21: 3041 | E21: 2906 | F21: 2868 | G21: 3354 | H21: 3791 | I21: 3385 | J21: 3687 | K21: 3304
A22: Employee Cost | B22: 1743 | C22: 1860 | D22: 1875 | E22: 1820 | F22: 2358 | G22: 2545 | H22: 2854 | I22: 3009 | J22: 2952 | K22: 3175
A23: Selling and admin | B23: 6689 | C23: 7252 | D23: 7796 | E23: 7620 | F23: 7906 | G23: 8164 | H23: 8785 | I23: 10780 | J23: 10145 | K23: 10744
A24: Other Expenses | B24: 1470 | C24: 1480 | D24: 1553 | E24: 1688 | F24: 2195 | G24: 2359 | H24: 2267 | I24: 2806 | J24: 2966 | K24: 3051
A25: Other Income | B25: 606 | C25: 353 | D25: 322 | E25: 424 | F25: 170 | G25: 219 | H25: 448 | I25: 817 | J25: 1355 | K25: 4923
A26: Depreciation | B26: 432 | C26: 520 | D26: 565 | E26: 1002 | F26: 1074 | G26: 1091 | H26: 1137 | I26: 1216 | J26: 1253 | K26: 1333
A27: Interest | B27: 35 | C27: 26 | D27: 33 | E27: 118 | F27: 117 | G27: 106 | H27: 114 | I27: 334 | J27: 381 | K27: 410
... A31: Dividend Amount | B31: 3672 | C31: 4320 | D31: 4752 | E31: 5400 | F31: 9517.5 | G31: 7990 | H31: 9165 | I31: 9870 | J31: 12455 | K31: 9635
A32: Effective Tax Rate | B32: =B29/B28 -> 0.30570589 | C32: =C29/C28 -> 0.28456064 | D32: =D29/D28 -> 0.29567643 | E32: =E29/E28 -> 0.26284779 | F32: =F29/F28 -> 0.24573314 | G32: =G29/G28 -> 0.25145214 | H32: =H29/H28 -> 0.23988309 | I32: =I29/I28 -> 0.26166882 | ... K32: =K29/K28 -> 0.1734453
A34: EBITDA | B34: =+B30+B29+B27+B26 -> 6920 | C34: =+C30+C29+C27+C26 -> 7839 | D34: =+D30+D29+D27+D26 -> 9196 | E34: =+E30+E29+E27+E26 -> 10277 | F34: =+F30+F29+F27+F26 -> 11792 | G34: =+G30+G29+G27+G26 -> 13063 | H34: =+H30+H29+H27+H26 -> 14572 | I34: =+I30+I29+I27+I26 -> 15471 | ... K34: =+K30+K29+K27+K26 -> 19943
A40: Quarters
A41: Report Date | B41: 45291 | C41: 45382 | D41: 45473 | E41: 45565 | F41: 45657 | G41: 45747 | H41: 45838 | I41: 45930 | J41: 46022 | K41: 46112
A42: Sales | B42: 15567 | C42: 15210 | D42: 15707 | E42: 15926 | F42: 15556 | G42: 15190 | H42: 16514 | I42: 15919 | J42: 16441 | K42: 16351
A43: Expenses | B43: 11902 | C43: 11675 | D43: 11965 | E43: 12139 | F43: 11867 | G43: 11572 | H43: 12797 | I43: 12137 | J43: 12660 | K43: 12514
A44: Other Income | B44: 184 | C44: 309 | D44: 209 | E44: 203 | F44: 733 | G44: 149 | H44: 74 | I44: 269 | J44: 4048 | K44: 503
A45: Depreciation | B45: 313 | C45: 320 | D45: 329 | E45: 338 | F45: 318 | G45: 318 | H45: 361 | I45: 322 | J45: 337 | K45: 348
